Workbook

Sheet 座位表
B1: 讲台 | E1: 屏幕
A4: 第一排 | B4: 1 | C4: 2 | D4: 3 | E4: 4 | G4: 5 | H4: 6
C5: 金智宸 | D5: 陈一实 | E5: 何奇阳 | G5: 祁靖轩
A7: 第二排 | B7: 7 | C7: 8 | D7: 9 | E7: 10 | G7: 11 | H7: 12
B8: 张允泽 | C8: 张岳琳 | D8: 刘孟霖 | E8: 杜星澎 | G8: 熊子轩 | H8: 张梓涵
B10: 13 | C10: 14 | D10: 15 | E10: 16 | G10: 17 | H10: 18
B11: 邓宇然 | C11: 吴奕淳 | D11: 练皓文 | E11: 郭维皓 | G11: 张世昌 | H11: 余廷锴

Sheet 名单
A1: 姓名 | B1: ACGO名称 | C1: 备注
A2: 吴奕淳
A3: 刘孟霖 | B3: 13710027021
A4: 张岳琳 | B4: 13533822630
A5: 张允泽 | B5: 13922270909
A6: 邓宇然 | B6: 17328656876
A7: 杜星澎 | B7: 18818808705
A8: 何奇阳 | B8: 13543432703
A9: 郭维皓 | B9: 15920102120
A10: 练皓文 | B10: 13763344727
A11: 欧阳陈果 | B11: 13450361549
A12: 陈一实 | B12: 13760684651
A13: 金智宸 | B13: 13570963605
A14: 祁靖轩 | B14: 13928739882
A15: 张梓涵 | B15: 15820252602
A16: 熊子轩
A17: 张世昌
A18: 余廷锴
A19: 林君昊

Sheet day1
A1: 课程内容 | B1: 姓名 | C1: 课堂积极性 | D1: 代码能力 | E1: 理解能力 | F1: 综合评价 | G1: 总结 | H1: 反思 | I1: 计划 | J1: 反馈结果 | K1: 总评 | L1: 课堂积极性 | M1: 理解能力 | N1: 代码能力
A2: 今天主要复习提高组的算法模板，首先讲解了各种模板的基础功能，然后重点介绍了各种模板在实际问题中的使用技巧。 | B2: 陈一实 | C2: A- | D2: A | E2: A | F2: A | G2: 最优解问题、图上和树上相关问题、动态规划。 | H2: 数组开的太大没有发现，多写了一个0，结果导致这个题0分了。有个题审题不仔细，丢掉了十分。 | I2: 找状态压缩DP的题目训练,以及一些图论上的相关知识点的题目，还有一些烧脑的知识点。 | J2: 今天我们主要复习了提高组的算法模板，首先讲解了各种模板的基本功能，然后重点介绍了如何在实际问题中应用这些模板。 陈一实同学能够深入理解各类算法模板的功能，并且在课堂上能够灵活选择和组合，思路清晰，条理分明，能够根据不同题型提出合适的算法策略。在测试中，他能迅速将常用模板应用到具体题目中，编写代码时能根据问题的特点判断并调用最合适的算法，表现出对算法模板的扎实理解。在代码方面，陈一实同学在剩余题目中能够做对自己熟悉的题，并且对于一些不会的题，也能针对部分分数写出代码。不过在做一些思维题时，还需要更多的思考，深入理解题意后再开始编写代码。继续加油！ | K2: =IF(D2="A",1,0)*30+IF(D2="B",1,0)*20+IF(D2="C",1,0)*10+IF(E2="A",1,0)*30+IF(E2="B",1,0)*20+IF(E2="C",1,0)*10+IF(F2="A",1,0)*30+IF(F2="B",1,0)*20+IF(F2="C",1,0)*10 -> 90 | L2: 【xx】同学能够深入理解各类算法模板的基础功能，并在课堂中中灵活选用和组合，思路清晰，条理分明，能够针对不同题型提出不同的算法策略。 | M2: 在剩下的题目里，【xx】能把自己会做的题做对，并且对于一些不会做的题，【xx】也能针对部分分去写代码，不过在做一些思维题的时候，孩子需要多些思考，对于题目往深处想一想，再开始编写代码，继续加油。 | N2: 【xx】能将提高组常用模板迅速套用到具体题目中，编写代码时能够根据问题特点判断并调用最合适的算法，说明对于算法模板的理解非常到位。
B3: 何奇阳 | C3: A- | D3: B+ | E3: A | F3: A- | G3: 复习了dp,树的直径，以及一系列图论树论知识点。尤其是加深了dp算法的思考范式。关于字符串哈希，我原本几乎忘了，现在重新学习了一遍。并且深刻了解了其运用。另外我还了解到map是一个多么好用的数据结构。复习了状态压缩dp | H3: 考试时间安排不好。死磕线段树实在太伤，完事后也就没几分钟了，后面需要思维的题目因此没有机会完成。 | I3: 树状数组和st表,lca算法需要进行深化，避免线段树单一路径依赖。树上问题的一些模版需要继续熟练一下、 | J3: 今天我们主要复习了提高组的算法模板，首先讲解了各类模板的基本功能，然后重点介绍了它们在实际问题中的应用技巧。 何奇阳同学对各类算法模板的基础功能理解到位，并且在课堂上能灵活选用和组合，思路清晰，条理分明，能够根据不同题型提出相应的算法策略。在测试中，何奇阳大部分题目都能找到合适的算法，并能够运用常见模板解决问题。不过，在一些较为困难的题目中，仍有一些小问题需要注意。 在代码方面，何奇阳能顺利完成自己熟悉的题目，并且对于一些不会做的题，能够争取部分分数，通过编写代码去解决。不过，在做思维性较强的题目时，还需要更多的思考。建议在理解题意后，多从不同角度深入思考，再开始写代码。继续加油，相信会越来越好！ | L3: 【xx】同学对算法模板的基本功能掌握扎实，但在实际应用时偶有纰漏，后续会督促多加练习，强化模板选择与使用的小技巧。 | M3: 【xx】同学已经掌握了ST表的核心概念，能够独立完成稀疏表的构建和最小/最大值查询。但是在具体题目中的运用还存在一些模糊的地方，后续我们还会进行专项练习 | N3: 【xx】在大部分题目上都能找到相对应的算法，能够采用常见模板来解决问题。但是在一些比较困难的问题中有些纰漏。
B4: 祁靖轩 | C4: B+ | D4: A | E4: A- | F4: A- | G4: 以子问题的形式展开复习了提高组的算法及对应模板,并进行了模拟赛练习,初步学习了状压DP和哈希,并进一步学习了如何求子串的哈希值 | H4: 考试时因为一个小细节没写对而导致整题出错(T10存负数下标忘记使用map) | I4: 多学习一下状压DP，练习一下相关的题目。 | J4: 今天我们复习了提高组的算法模板，首先讲解了各种模板的基本功能，然后重点分享了它们在实际问题中的应用技巧。 祁靖轩同学对算法模板的基础功能掌握得比较扎实，但在实际应用时偶尔出现一些小失误。后续我会鼓励他多加练习，进一步巩固模板选择和使用的小技巧。 在测试中，祁靖轩能够迅速将常用模板应用到具体题目中，编写代码时也能根据问题的特点准确判断并调用最合适的算法，展现了对算法模板的较好理解。 在代码方面，祁靖轩能在剩下的题目中做对自己熟悉的部分，并且在一些不熟悉的题目上也能尽力争取部分分数，表现不错。对于一些思维性较强的题目，建议他多花点时间思考，深入理解题意后再动手写代码。继续保持，加油！ | L4: 在剩下的题目里，【xx】能针对部分分去写代码，不过在做一些思维题的时候，孩子需要多些思考，对于题目往深处想一想，再开始编写代码，继续加油。 | M4: 在剩下的题目里，【xx】能把自己会做的题做对，并且对于一些不会做的题，煜涵也能针对部分分去写代码，不过在做一些思维题的时候，孩子需要多些思考，对于题目往深处想一想，再开始编写代码，继续加油。 | N4: 【xx】对于题目类型的建模能力以及提高组基础模板的掌握程度还有所欠缺，经常会在题目的思路构建阶段卡住，后续将会通过不断地练习来提升建模能力。
B5: 张允泽 | C5: A- | D5: A- | E5: A | F5: A- | G5: 今天复习了x04学习的提高组算法，如dp，图论，数论等算法，学习了状态压缩DP，以及学习了一些在复赛中的解题技巧。 | H5: 今天在oi赛制的测试中，没有考虑2^1000超出了长整型的范围，使用了“前缀乘”，导致long long类型数据溢出，第8题数据范围超限只拿到了20分。 | I5: 继续了解状压dp,学习其原理以及运用，在以后的学习中灵活使用该算法 | J5: 今天我们复习了提高组的算法模板，首先讲解了各种模板的基本功能，然后重点介绍了它们在实际问题中的应用技巧。 张允泽同学对算法模板的基础功能掌握得很好，并且在课堂上能够灵活选用和组合，思路清晰，条理分明，能够根据不同题型提出有效的算法策略。 在测试中，张允泽能够快速将提高组常用的模板应用到具体题目中，编写代码时能根据问题特点选择并调用最合适的算法，表现出对算法模板的深入理解。 在代码方面，张允泽能够顺利解决自己擅长的题目，对于一些不熟悉的题目，也能争取部分分数，通过写代码尝试解决。对于一些较为复杂的思维题，建议他多思考，进一步挖掘题目的深层次含义，再着手编写代码。继续努力，相信会有更大进步！
B6: 张岳琳 | C6: A- | D6: B+ | E6: A | F6: A- | G6: 今天学到了状压dp，回忆起了树的重心、哈希、多组询问、最优解问题、图的问题、树的问题 | H6: 模拟题第1题忘写数组名导致没过样例，第3题没开long long导致没过样例 | I6: 多练习哈希、树的问题，多练习状压dp的题目 | J6: 今天我们主要复习了提高组的算法模板，首先介绍了各种模板的基本功能，并着重讲解了如何在实际问题中灵活运用这些模板的技巧。 张岳琳同学对各类算法模板的基本功能理解很好，能够在课堂上灵活运用并有效组合，思路清晰且条理性强，能够根据不同题型提出合适的算法策略。 在今天的测试中，张岳琳能在大部分题目中找到适用的算法，并顺利应用常见模板解决问题。然而，由于今天的测试采用了OI赛制，之前没有经过相关的训练，这导致在一些较难题目的处理上，张岳琳在代码细节上出现了一些问题，错失了不少分数。 在代码方面，张岳琳能准确完成自己熟悉的题目，对于不太擅长的题目，也会尽力尝试写出部分正确的代码，争取部分分数。对于思维类题目，建议张岳琳在今后的训练中多加练习，特别是细节处理和优化方面，增强应对赛制题目的能力。继续努力，相信随着更多的训练，成绩会越来越好！
B7: 刘孟霖 | C7: B+ | D7: A- | E7: A | F7: A- | G7: 今天复习了 前缀和，ST表，树状数组，逆序对(计数数组)，二分答案，贪心，dfs枚举，动态规划，最短路，并查集，最小生成树，树的直径，树的重心，树上差分等算法 | H7: 在做“快来数一数”的时候把2e5开成了1e5导致数组RE，导致没有完全通过；在做“数星星”的时候因为算法思路方向错误导致没有完全通过。 | I7: 后续计划：复习树的直径和树的重心算法，多默写几遍ST表模板，多做点树的直径和树的重心知识点相关的题目； | J7: 今天我们主要复习了提高组的算法模板，首先系统地讲解了各类模板的基本功能，并结合实际问题探讨了如何灵活使用这些模板来提高解题效率。 刘孟霖同学对算法模板的理解非常扎实，不仅能够清楚地掌握每个模板的功能，还能在课堂中自如地选择并组合使用，展现出了清晰的思路和条理性。他能够根据不同题型快速分析并提出相应的算法策略，解决问题的思路非常灵活。在测试中，刘孟霖能迅速识别并应用提高组常见的模板来解题，整体表现优秀。 不过，在面对一些较为复杂的题目时，刘孟霖有时处理得不够细致，可能是因为在问题的深入分析上还可以加强一些。他在思考过程中偶尔略显匆忙，建议他在今后的学习中，可以尝试在遇到难题时稍作停顿，仔细推敲每一个细节。 在代码方面，刘孟霖能顺利完成自己熟悉的题目，且在解决不会做的题时，能够有效地争取部分分数，这展现了他良好的思维能力和应变能力。对于一些较为抽象的思维题，建议他加强对题目的整体分析，不仅要关注题目的表面信息，更要深入挖掘题目的深层含义，找到最佳的解法。 总的来说，刘孟霖同学的解题思路和能力都表现得非常好，虽然有些细节还需要打磨，但他的努力和进步是显而易见的。继续加油，相信在未来的学习中，能够取得更加优异的成绩！
B8: 杜星澎 | C8: A- | D8: A- | E8: A | F8: A- | G8: 知识巩固：点权树上查分，状压DP； 新知学习：Floyd判负环，树形（换根）DP求树的重心。 | H8: LCS的DP板子忘记了，当时思路也十分混乱，导致T5 0pts； 倍增LCA的空间开得太大了（题目空间开的太小了，就开了128MB，CSP是256/512MB），同时函数内部lg取值错误，出现了RE+MLE的错误，可能自己当时对倍增的过程还是不够理解，导致T7 0pts； 贪心没有想对，字符串哈希没有想到，结果std是线性模拟，可能是考场上没有想到特殊性质，导致只骗了10pts； T10和T11赛时没有思路，看完题目就跑了，下次还是要先看一下特殊性质，再多骗一点，而不是追求AC。 | I8: 状压DPT1还是挺好想的，但是T2依然没有调出来，其实状压DP的状态设计是很显然的，但总是在位运算时出错，看来菜还是得多练。 | J8: 今天主要复习了提高组的算法模板，先讲解了各类模板的基本功能，再结合实例探讨了它们在不同题型中的应用技巧。杜星澎同学对模板的理解较为深入，在课堂上能够灵活选择与组合使用，思路清晰，条理分明，能针对不同题型提出合适的算法方案。在测试中，他大部分题目都能准确找到匹配的模板并加以应用，代码实现稳健，思路基本正确。 不过在两道较为基础的模板题上，由于 OI 赛制下未及时发现细节问题而出现了小失误，虽然不影响整体解题方向，但提示在赛制环境中还需对细节保持更高的敏感度。整体表现可圈可点，若能在细节检查和赛制适应上再加强，相信成绩会更加稳定。
B9: 熊子轩 | C9: A- | D9: A | E9: A- | F9: A- | G9: 复习提高组算法：如前缀和，st表，树状数组， 最优解问题：二分，贪心，枚举，最短路 找父母问题：树状数组，并查集，最小生成树 图上问题的算法：弗洛伊德；dij，spfa 树上问题：换根dp，树上前缀和与差分 | H9: lca题目中for循环边界值写错了，考试时时一些能通过暴力或特殊样例骗分的没拿到 | I9: 动态规划问题的状态转移方程，多做一些dp题目，练习更加熟练推导状态转移方程 | J9: 今天主要复习了提高组的算法模板，先讲解了各类模板的基础功能，再结合实例分析了它们在实际问题中的运用技巧。熊子轩同学对模板的理解比较到位，在课堂中能灵活选用与组合，思路清晰，条理分明，能够针对不同题型提出恰当的算法方案。在测试中，他能迅速将常用模板应用到具体题目中，代码编写稳健，整体表现积极。 不过在模板题部分，有一道题因细节处理不够严谨而失分较多；而在思维题部分，他采用了多道题的暴力解法，虽然没有完全解出最优解，但也凭借这种策略拿到了可观的分数。若能在细节检查上更加严谨，并在思维题中多尝试优化思路，成绩还有进一步提升的空间。
B10: 张梓涵 | C10: A | D10: B+ | E10: A | F10: A- | G10: 今天复习了几乎整个CSP-S常用的算法以及数据结构，同时打了场OI赛制比赛，学到了一些在OI赛制比赛中的技巧，晚上也学习了如何拿到题目的部分分，也学习了一下状压DP | H10: 在比赛中，我由于总是忘记读题并开合适的数组大小，导致失了200分，同时默模版时写错了一个字符，导致又失了100分，直接掉到了第8。 | I10: 我要在写题时重新认真读一遍题目，认真对待每道题，以后不犯数组开小了导致RE的这种低级错误 | J10: 今天主要复习了提高组的算法模板，先讲解了各类模板的基本功能，再结合实例探讨了它们在不同题型中的应用方法。张梓涵同学思维活跃，上课积极发言，听课认真，对算法模板的理解较为到位，能够在课堂中灵活选用和组合，思路清晰，条理分明，能针对不同题型提出合理的解题思路。在测试中，他在思维题部分表现突出，拿下了不少分数，展现了较强的分析与解决问题能力。 不过，由于对 OI 赛制还不够熟悉，前面多道模板题在实现中出现了错误且未能及时察觉，造成了一定的失分。建议在平时多进行赛制环境下的练习，培养对细节的敏感度和及时检查的习惯，这样在保持思维题优势和课堂积极性的同时，也能在模板题上稳住分数。
B11: 邓宇然 | C11: A- | D11: B | E11: A- | F11: A- | G11: 图上问题（迪杰斯特拉，弗洛伊德，spfa），区间动态规划，状态压缩动态规划，树上问题（树的直径） | H11: 代码数组范围开小了导致RE，拓展题没什么思路，只能写了一些部分分 | I11: 动态规划，要多练习，并且记忆模板 | J11: 今天我们复习了提高组的算法模板，首先讲解了各种模板的基础功能，并重点分享了它们在实际问题中的应用技巧。 邓宇然同学对各类算法模板的基础功能掌握扎实，能够灵活选用和组合，思路清晰、条理分明，能够根据不同题型提出有效的算法策略。在测试中，邓宇然能够在大部分题目中找到合适的算法，并成功运用常见模板解决问题。 然而，由于今天采用了OI赛制，邓宇然没有经过足够的相关训练，导致在一些细节上出现了疏漏，丢失了不少分数，最终排名不如预期。尤其在处理复杂题目时，一些小细节的错误影响了整体得分，值得在之后的训练中加以重视。 在代码方面，邓宇然能够准确完成自己擅长的题目，对于一些较难的题目，虽然没有完全解出，但也能争取部分分数，展现了很好的应变能力。对于思维性较强的题目，建议他在之后的训练中注重细节的练习，尤其要强化在赛制环境下的时间管理和细节检查，确保在面对复杂问题时不漏掉关键点。继续加油，相信通过更多的训练，能在未来取得更好的成绩！
B12: 吴奕淳 | C12: A- | D12: A- | E12: A | F12: A- | G12: 今天学习了区间dp，状压dp，树的直径，树的重心，拓扑，迪杰斯特拉，弗洛伊德，SPFA等知识点 | H12: 今天在树状数组2的题目中，由于因为没写负号，导致没有完全通过；最近树的直径中，由于没开long long，导致没有完全通过。 | I12: 要在空余时间中多默写树状数组，最长公共子序列，最近公共祖先等模板，增强记忆；多练习dp，树上问题，图上问题等知识点相关题目，提升代码能力。 | J12: 今天我们复习了提高组的算法模板，首先讲解了各种模板的基础功能，并重点介绍了它们在实际问题中的应用技巧。 吴奕淳同学对各类算法模板的基础功能理解非常扎实，能够灵活运用并进行有效组合，思路清晰且条理分明，能够根据不同题型提出切实可行的算法策略。在测试中，吴奕淳能够迅速将提高组常用模板套用到具体题目中，编写代码时能够根据问题的特点判断并调用最合适的算法，表现出对算法模板的深入理解。 不过，由于今天采用了OI赛制，吴奕淳在赛制的适应性上稍有欠缺，特别是在一些模板题上，由于不够熟练，导致细节处理不当，错失了一些分数。如果能够在模板题的应用上更加熟练，排名肯定会更高。 在思维性较强的题目上，吴奕淳展现出了很强的思维能力，能够快速深入分析题目并找到解决方案，做对了很多复杂的题目，体现了非常优秀的解题潜力。 建议吴奕淳继续加强对OI赛制下模板题目的练习，尤其是细节和时间管理方面，这样可以更好地提升整体得分和排名。继续加油，凭借他的思维能力和不断努力，成绩一定会越来越好！
B13: 练皓文 | C13: A- | D13: B | E13: A | F13: A- | G13: 学习了状态压缩DP及其代码的实现，回忆了树上差分、树的直径、LCA等知识点。 | H13: 在做后四题的时候，在代码细节处理上有失误，没有注意到题目中的提示等信息，也没有准确地分析样例以及题意，导致部分没有通过。 | I13: 多写几道关于状压DP的题目，加强理解；多写关于树上差分的代码，增强理解；多写LCA的模板，提升熟练度。 | J13: 今天主要复习了提高组的算法模板，先讲解了各种模板的基本功能，再重点介绍了它们在实际问题中的应用技巧。练皓文同学对大部分模板的基础原理能够理解透彻，在课堂中能灵活选用和组合，思路清晰，条理分明，能够针对不同题型提出相应的算法思路。在测试中，大部分题目他都能找到合适的解法，并能运用常见模板加以解决。 不过在一些难度较高、需要综合思考的题目中，练皓文有时在模板的细节使用上还略显生疏，导致思路切换和代码实现上存在一定波动。在代码方面，他能把自己掌握的题目正确完成，对于不太熟悉的题型，也会尽量争取部分分；但在思维性较强的问题上，还需要在理解题意和方案设计上多花一些时间，深入分析后再动手编写代码。整体表现良好，期待他在模板的熟练度和复杂问题的应对上进一步提升。
B14: 郭维皓 | C14: A- | D14: B+ | E14: A | F14: A- | G14: 状压DP，多组询问，最优解问题，和树的父节点相关问题，图上问题，树上问题等 | H14: 对OI赛制不熟悉，没有注意到左移会炸导致T1只过了两个点 | I14: 在二进制枚举和字符串哈希方面要多做一些相关题目，增进对知识点的理解与题目熟练度 | J14: 今天主要复习了提高组的算法模板，先系统梳理了各类模板的核心功能，随后结合实例探讨了它们在不同题型中的应用方法。郭维皓同学对常用模板的原理掌握较为扎实，在课堂练习中能够根据题目的特征进行选择和组合，整体思路清楚，步骤安排合理。在测试中，他在大部分题目中都能找到匹配的解法，并运用相应模板解决问题。 不过在应对一些结构更复杂、条件更隐蔽的题目时，模板的选用和细节处理上还稍显生涩，有时需要花费较长时间才能稳定切入正确方向。在代码实现上，他能准确完成自己熟悉的题型，对于陌生的题目也会积极争取部分分，但在思维跳跃较大的题目中，还需要进一步提高分析的深度与灵活性。整体表现积极，期待他在模板熟练度和复杂情境下的适应力上继续提升。
B15: 张世昌 | C15: A- | D15: A- | E15: A | F15: A- | G15: 今天我回忆起了多组查询类的问题，比如前缀和、ST表、树状数组，还回忆起了一些最优解问题的算法，想起了二分、贪心、最短路等算法，我们还学习了一些关于找父母问题的算法，比如并查集可以解决连通性问题，LCA可以找最近公共祖先，还回忆起了一些图论、树论算法，知道了各种算法的优缺点，考试时可以根据题目知道那些算法可以用，那些算法不能用，今天的重点就是动态规划了，针对最值问题、计数问题、可行性问题时，可以用不同的动态规划，今天学到最深刻的就是写动态规划的步骤了：1.设计状态，2.初始化，3.状态转移方程，4.枚举顺序，5.输出答案。 | H15: 在今日测试中，可以暴力拿到得分没有拿到，点击提交次数太多 RE了，数据范围开太大，MLE了 | I15: 多练习一些动态规划的题目，练习如何设计状态，初始化等步骤。 | J15: 今天主要复习了提高组的算法模板，先讲解了各类模板的核心功能，再结合实例分析了它们在实际问题中的运用技巧。张世昌同学对模板的理解非常深入，不仅能准确掌握各类算法模板的原理，还能在课堂中灵活组合运用，思路清晰、条理分明。在测试中，他能够快速判断并选择最合适的模板进行求解，且在 OI 赛制下表现稳定，几乎没有明显失误，代码实现细致而可靠，展现了扎实的编程功底。 不过在涉及思维跨度较大、需要发散或多角度切入的题目时，还可以在分析的广度和深度上进一步加强，以便在遇到新颖题型时也能迅速找到突破口。整体而言，他在模板应用和代码能力上优势明显，后续若能在思维能力上再提升一步，综合实力会更上一层楼。
B16: 余廷锴 | C16: A- | D16: A | E16: A- | F16: A- | G16: 回忆了有关于多组询问问题，最优解问题，图上问题的解题方法，如并查集，LCA等，学到了有关动态规划（dp)的部分知识。 | H16: 并查集模板记忆模糊，STL运用不熟练，部分步骤分没有拿全。 | I16: 有关状态压缩dp的题目与各个模板题目仍需多多练习 | J16: 今天主要复习了提高组的算法模板，先讲解了各类模板的核心功能，再结合实例分析了它们在不同题型中的应用技巧。余廷锴同学思维能力突出，在课堂中能够灵活选用和组合模板，思路清晰，条理分明，能够针对不同题型提出合理的算法策略。在测试中，他在思维题部分表现尤为亮眼，拿下了班级第二的高分，充分展现了出色的分析与解决问题能力。 在模板题方面，大部分掌握得很扎实，仅有极少部分模板还不够熟练，偶尔影响了得分。建议在保持思维优势的同时，针对这些薄弱模板进行专项巩固，这样可以在各类题型中都发挥稳定的水平。整体表现优秀，继续保持！
B17: 金智宸 | C17: A- | D17: A | E17: A- | F17: A- | G17: 多组询问/最优解/图上/树论问题，动态规划，状压dp，由多维用二进制压缩至2维的顶尖技术 | H17: 模版记得不清晰，数组开小导致越界，没审题仔细。 | I17: 多练习有关动归的题目，多背点模板，复习点旧知识，再扣点细节。 | J17: 今天主要复习了提高组的算法模板，先讲解了各类模板的核心功能，再结合实例分析了它们在不同题型中的应用方法。金智宸同学对模板的掌握非常扎实，课堂中能够灵活选用与组合，思路清晰，条理分明，能针对不同题型快速制定合适的解题方案。在测试中，他能够熟练地将常用模板应用到具体题目中，代码实现准确且稳定。 不过，在一题中因对 OI 赛制还不够熟悉，未能及时发现并修正错误，造成了少量失分。好在后续的模板题中，他把能争取的部分分全部拿到，展现了良好的赛中调整能力。整体表现优秀，如果在赛制细节上再多加熟悉，相信成绩会更加稳固。
B18: over | C18: B | D18: B | E18: B | F18: B | J18: =A$2&""&SUBSTITUTE(IF(OR(C18="A",C18="A-",C18="A+"),L$2,IF(OR(C18="B",C18="B-",C18="B+"),L$3,L$4)),"【xx】",B18)&"在测试中，"&SUBSTITUTE(IF(OR(D18="A",D18="A-",D18="A+"),N$2,IF(OR(D18="B",D18="B-",D18="B+"),N$3,N$4)),"【xx】",B18)&"在代码方面，"&SUBSTITUTE(IF(OR(E18="A",E18="A-",E18="A+"),M$2,IF(OR(E18="B",E18="B-",E18="B+"),M$3,M$4)),"【xx】",B18)&""&SUBSTITUTE(IF(OR(F18="A",F18="A-",F18="A+"),O$2,IF(OR(F18="B",F18="B-",F18="B+"),O$3,O$4)),"【xx】",B18) -> 今天主要复习提高组的算法模板，首先讲解了各种模板的基础功能，然后重点介绍了各种模板在实际问题中的使用技巧。over同学对算法模板的基本功能掌握扎实，但在实际应用时偶有纰漏，后续会督促多加练习，强化模板选择与使用的小技巧。在测试中，over在大部分题目上都能找到相对应的算法，能够采用常见模板来解决问题。但是在一些比较困难的问题中有些纰漏。在代码方面，over同学已经掌握了ST表的核心概念，能够独立完成稀疏表的构建和最小/最大值查询。但是在具体题目中的运用还存在一些模糊的地方，后续我们还会进行专项练习
B19: over | C19: A+ | D19: A+ | E19: A+ | F19: A+ | G19: LCA,并查集,树状数组,DFS,DP(01，状压，完全，树上......),单源最短路,贪心,前缀和,智商的重要性,数论,图论,ST表,STL,暴力出奇迹,exgcd,数学,拓扑排序,判断负环...... | H19: 模板错了一道，不看完题就写导致测完样例还得再写1,2遍，时间没把握好，没检查......长得太帅了 | I19: 灵感的获取 | J19: 今天主要复习提高组的算法模板，首先讲解了各种模板的基础功能，然后重点介绍了各种模板在实际问题中的使用技巧。煜涵同学能够深入理解各类算法模板的基础功能，并在课堂中中灵活选用和组合，思路清晰，条理分明，能够针对不同题型提出不同的算法策略。在测试中，煜涵能将提高组常用模板迅速套用到具体题目中，编写代码时能够根据问题特点判断并调用最合适的算法，说明对于算法模板的理解非常到位。在剩下的题目里，煜涵能把自己会做的题做对，并且对于每一道题都能自己写一份暴力程序，这个习惯非常好，继续保持。
B20: 康煜琦 | C20: B | D20: A- | E20: B+ | F20: A- | G20: 树状数组 线性dp 状压dp 资源分配dp 并查集 dfs枚举 树的直径 两个不同数组的dp（忘记叫什么了 最短路 LCA 数论 树上差分 树上差分 差分 前缀和 ST表 bfs 最小生成树 记忆化 组合数学 二分 逆序对 负环 单调队列 单调栈 SPFA Dijkstra FLoyd Kruskal Prim STL | H20: 树状数组 线性dp 状压dp 资源分配dp 并查集 dfs枚举 树的直径 两个不同数组的dp（忘记叫什么了 最短路 LCA 数论 树上差分 树上差分 差分 前缀和 ST表 bfs 最小生成树 记忆化 组合数学 二分 逆序对 负环 单调队列 单调栈 SPFA Dijkstra FLoyd Kruskal Prim STL | I20: 来自洛谷 P3390 【模板】矩阵快速幂 | J20: 今天主要复习提高组的算法模板，首先讲解了各种模板的基础功能，然后重点介绍了各种模板在实际问题中的使用技巧。煜琦同学能够深入理解各类算法模板的基础功能，并在课堂中中灵活选用和组合。在测试中，煜琦在大部分题目上都能找到相对应的算法，能够采用常见模板来解决问题。但是在一些比较困难的问题中有些纰漏例如树的直径，最长公共子序列这块有些不熟练，在课上也讲解了树的直径的相关知识点，煜琦可以再去练习下。在剩下的题目里，煜涵能把自己会做的题做对，并且对于一些不会做的题，煜涵也能针对部分分去写代码，不过在做一些思维题的时候，孩子需要多些思考，对于题目往深处想一想，再开始编写代码，继续加油。
B21: 仲钧维 | C21: B | D21: A+ | E21: A | F21: A | G21: 孩子总结写的不认真，明天会监督孩子完成总结 | H21: 不会用Map | I21: 无 | J21: 今天主要复习提高组的算法模板，首先讲解了各种模板的基础功能，然后重点介绍了各种模板在实际问题中的使用技巧。钧维同学能够深入理解各类算法模板的基础功能，并在课堂中中灵活选用和组合，思路清晰，条理分明，能够针对不同题型提出不同的算法策略。在测试中，钧维在大部分题目上都能找到相对应的算法，能够采用常见模板来解决问题。但是在一些比较困难的问题中有些纰漏。在剩下的题目中，钧维能够确保将自己会做的题目都正确解答，同时对于每道题目会针对部分分去实现代码。这种严谨的解题态度和良好的编程习惯值得继续保持。
B22: 韩谨泽 | C22: B | D22: B | E22: B | F22: B | G22: 复习了动态规划（线性动态规划、树形动态规划）、拓扑排序、枚举、多种模版（并查集、树状数组 、树的直径、最长公共子序列、单源最短路径、最近公共祖先）的写法。 了解到自己对于模版生疏的问题。 | H22: 面对难题缺少思路与技巧，对于模版的生疏 | I22: 模板的记忆背诵，对错误题目的分析总结 | J22: 今天主要复习提高组的算法模板，首先讲解了各种模板的基础功能，然后重点介绍了各种模板在实际问题中的使用技巧。谨泽同学对算法模板的基本功能掌握扎实，但在实际应用时偶有纰漏，后续会督促多加练习，强化模板选择与使用的小技巧。在测试中，谨泽在大部分题目上都能找到相对应的算法，能够采用常见模板来解决问题。但是在一些比较困难的问题中有些纰漏。在剩下的题目里，谨泽能针对部分分去写代码，不过在做一些思维题的时候，孩子需要多些思考，对于题目往深处想一想，再开始编写代码，继续加油。
B23: 徐恺睿 | C23: B | D23: B+ | E23: B+ | F23: B+ | G23: 树状数组1、并查集、差分数组、树的直径、最长公共子序列、单源最短路径、树状数组2、前缀和、STL容器、树上差分、状压DP、记忆化、树上DP、背包DP、区间DP、最小生成树、组合数学、二分答案、暴力、边权、邻接表、双指针、逆序对、负环、图论、ST表、堆、LCA、Dijkstra、SPFA、FLoyd、Kruskal、Prim、BFS、DFS、LCS、MST | H23: 提高组算法模板LCS没默出来 | I23: LCS、记忆化、树上DP、MST | J23: 今天主要复习提高组的算法模板，首先讲解了各种模板的基础功能，然后重点介绍了各种模板在实际问题中的使用技巧。恺睿同学能够深入理解各类算法模板的基础功能，并在课堂中中灵活选用和组合，思路清晰，条理分明，能够针对不同题型提出不同的算法策略。在测试中，恺睿在大部分题目上都能找到相对应的算法，能够采用常见模板来解决问题。但是在一些比较困难的问题中有些纰漏。在剩下的题目中，恺睿能够确保将自己会做的题目都正确解答，同时对于每道题目会针对部分分去实现代码。这种严谨的解题态度和良好的编程习惯值得继续保持。
B24: 周天翊 | C24: A+ | D24: B | E24: B | F24: B+ | G24: 多默写了亿点模板 | H24: 没有（吧） 没背模板被模板虐杀了（逃） 算法提高测试7-求和中的题目没有写出来这是一个重大的失误（虽然根本没记住awa） 最后一题时间不够没做出来（逃，当时在写树の直径） 很多细节的模板/没有记住，编码技巧/思维有待提高 | I24: 算法模板 模板组合技巧 题目分析 | J24: 今天主要复习提高组的算法模板，首先讲解了各种模板的基础功能，然后重点介绍了各种模板在实际问题中的使用技巧。天翊同学对算法模板的基本功能掌握扎实，天翊上课的时候非常积极，老师的每一个问题孩子都会回答，但在实际应用模版时偶有纰漏，后续会督促多加练习，强化模板选择与使用的小技巧。在测试中，天翊在大部分题目上都能找到相对应的算法，能够采用常见模板来解决问题。但是在一些比较困难的问题中有些纰漏，后续可以结合《书本》来复习下相关内容。在剩下的题目中，天翊能够确保将自己会做的题目都正确解答，同时对于每道题目会针对部分分去实现代码。这种和良好的编程习惯值得继续保持。
B25: 李震轩 | C25: B | D25: B | E25: A | F25: B+ | G25: 没写总结，明天会监督孩子写完 | J25: 今天主要复习提高组的算法模板，首先讲解了各种模板的基础功能，然后重点介绍了各种模板在实际问题中的使用技巧。震轩同学对算法模板的基本功能掌握扎实，但在实际应用时偶有纰漏，后续会督促多加练习，算法模版也是学习中非常重要的一部分，需要重视。在剩下的题目中，震轩的思维能力非常不错，获取了两道题的首 A，但是对于一些较难的题目，孩子没有很好的根据部分分去编写代码，这块需要注意。
B26: 张嘉润 | C26: B | D26: B | E26: B+ | F26: B | G26: 孩子总结写的不认真，明天会监督孩子完成总结 | H26: 忘了 | I26: dp、最短路 | J26: 今天主要复习提高组的算法模板，首先讲解了各种模板的基础功能，然后重点介绍了各种模板在实际问题中的使用技巧。，嘉润对算法模板的基本功能掌握扎实，但在实际应用时偶有纰漏，后续会督促多加练习，强化模板选择与使用的小技巧。在测试中，嘉润在大部分题目上都能找到相对应的算法，能够采用常见模板来解决问题。但是在一些比较困难的问题中有些纰漏，后续可以结合《书本》在对模版进行练习。在剩下的题目中，嘉润的思维能力非常不错，获取了两道题的满分，对于一些较难的题目，孩子会根据部分分去编写代码，这个良好的编程习惯值得继续保持。
B27: 李宇轩 | C27: A+ | D27: B | E27: B | F27: B+ | G27: 双序列问题： 1、双指针 2、树状数组 数据结构： 1、树状数组 2、STL容器 3、并查集 枚举： 1、for/while 2、DFS/BFS 3、二分答案（但是会比较少） 连通块问题 动态规划： 1、线性DP 2、状压DP 3*、记忆化搜索 4、区间DP | H27: 模板如树状数组、并查集等未掌握熟练 对输出的观察不够仔细 出现不注意数据背后大小的问题 树的直径掌握一半 | I27: 迪杰斯特拉和哈希以及最小生成树（克鲁斯卡尔、prim） | J27: 今天主要复习提高组的算法模板，首先讲解了各种模板的基础功能，然后重点介绍了各种模板在实际问题中的使用技巧。宇轩同学能够理解各类算法模板的基础功能，上课的时候非常积极，老师的每一个问题孩子都会回答。在测试中，宇轩在大部分题目上都能找到相对应的算法，能够采用常见模板来解决问题。但是在实现代码时有些纰漏，后续可以结合《书本》在对模版进行练习。在剩下的题目里，宇轩能针对部分分去写代码，不过在做一些思维题的时候，孩子需要多些思考，对于题目往深处想一想，再开始编写代码，继续加油。
B28: 杨涵语 | C28: B | D28: B | E28: B | F28: B | G28: 上午：提高组初赛大部分知识 举例如下： 动态规划：可用于求方案数、可行性、最值 线性动态规划（普通dp） 区间动态规划（在一段区间中进行操作，求出区间最值和……的方案数） 状态压缩动态规划：将二进制数当中，从右往左的每一位，对应集合中的每一个元素，可以用于求解01枚举方案数==> 可以拓展为多重枚举 双序列型动态规划：用于解决两个序列的问题，如最长公共子序列，最长公共子串 记忆化搜索：搜索优化 示例： if(dp[n][m]!=-1) return dp[n][m]; return dp[n][m]=f(…) 原理：通过提前记录曾经的搜索结果，省去不必要的时间浪费 最短路算法： 单源最短路：dijkstra,spfa（寄了） 多源最短路：Floyd 连通块问题： 1搜索2并查集（找爹） | H28: 忘记了树上直径模版应该如何书写，导致在今天的比赛中失去了两道题的分数， | I28: 离散化，krustal+prim | J28: 今天主要复习提高组的算法模板，首先讲解了各种模板的基础功能，然后重点介绍了各种模板在实际问题中的使用技巧。涵语同学对算法模板的基本功能掌握扎实，但在实际应用时偶有纰漏，后续会督促多加练习，强化模板选择与使用的小技巧。在测试中，涵语在大部分题目上都能找到相对应的算法，能够采用常见模板来解决问题。但是在实现代码时有些纰漏，后续可以结合《书本》在对模版进行练习。在剩下的题目里，涵语能针对部分分去写代码，不过在做一些思维题的时候，孩子需要多些思考，对于题目往深处想一想，再开始编写代码，继续加油。
B29: 赵可馨 | C29: B | D29: B+ | E29: B | F29: B | G29: 最短路 树状数组 最长公共子序列 并查集 lca 树的直径 组合数学 鸽巢原理 拓扑排序 背包dp 区间dp floyd dijkstra st表 | H29: 并查集没有压缩路径 导致超时 忘记了最长公共子序列 lca的数组爆了 导致MLE 没有估计好数据范围 然后就是不熟练 | I29: 板子不熟练 图论比较的难 那种要想结论的题还是比较的难想出来 | J29: 今天主要复习提高组的算法模板，首先讲解了各种模板的基础功能，然后重点介绍了各种模板在实际问题中的使用技巧。可馨同学对算法模板的基本功能掌握扎实，但在实际应用时偶有纰漏，后续会督促多加练习，强化模板选择与使用的小技巧。在测试中，可馨在大部分题目上都能找到相对应的算法，能够采用常见模板来解决问题。但是在一些比较困难的问题中有些纰漏。在剩下的题目里，可馨能针对部分分去写代码，不过在做一些思维题的时候，孩子需要多些思考，对于题目往深处想一想，再开始编写代码，继续加油。
B30: 葛义 | C30: B | D30: B | E30: B | F30: B | G30: 并查集、求积运算符、动态规划（01、完全、多重、树上、拓扑、换根）、鸽巢原理...... | H30: 并查集、动态规划以及图论内容没有多练习、实践 | I30: 并查集、动态规划以及图论内容 | J30: 今天主要复习提高组的算法模板，首先讲解了各种模板的基础功能，然后重点介绍了各种模板在实际问题中的使用技巧。葛义对于题目类型的建模能力以及提高组基础模板的掌握程度还有所欠缺，经常会在题目的思路构建阶段卡住，后续将会通过不断地练习来提升建模能力，可以结合发的书籍进行练习。
A31: 代码能力(当天最难的知识点 或 所有基础都理解就是A 或 班级表现前70%) A / B 理解能力(当天最难的知识点 或 所有基础都理解就是A 或 班级表现前70%) A / B 摸底测或代码模板默写(统称为小检测，4-5-1 对应A-B-C) A:30 B:20 C:10 最终表现 A类 >= 80分 B类 >= 60分 C类 < 60分

Sheet Day1反馈表
A1: 暑假集训学习反馈卡 | N1: 张陈曦暑假集训学习反馈卡
B4: 姓名 | D4: 熊子轩
B6: 课堂积极性 | D6: 理解能力 | F6: 代码能力 | H6: 综合评价
P7: 测试内容: CSP2022初赛真题
B8: =VLOOKUP(D4,day1!$B$1:$G$85,2,FALSE) -> A- | D8: =VLOOKUP(D4,day1!$B$1:$G$85,3,FALSE) -> A | F8: =VLOOKUP(D4,day1!$B$1:$G$85,4,FALSE) -> A- | H8: =VLOOKUP(D4,day1!$B$1:$G$85,5,FALSE) -> A- | P8: 基础选择得分 (满分30) | R8: 程序阅读得分 (满分40) | U8: 完善代码得分 (满分30) | W8: 总分 (浙江晋级线78.5)
P10: 30 | R10: 28.5 | U10: 30 | W10: =SUM(P10:V12) -> 88.5
B12: 学生总结 | C12: 收获 (今天学到了/回忆起了什么知识) | E12: =VLOOKUP(D4,day1!$B$1:$G$85,6,FALSE) -> 复习提高组算法：如前缀和，st表，树状数组， 最优解问题：二分，贪心，枚举，最短路 找父母问题：树状数组，并查集，最小生成树 图上问题的算法：弗洛伊德；dij，spfa 树上问题：换根dp，树上前缀和与差分
C14: 学生自我反思 (在测试/学习中出现了什么失误/错误) | E14: =VLOOKUP(D4,day1!$B$1:$J$85,7,FALSE) -> lca题目中for循环边界值写错了，考试时时一些能通过暴力或特殊样例骗分的没拿到 | P14: 学生总结 | Q14: 收获 (今天学到了/回忆起了什么知识) | T14: 二分查找、哈夫曼编码
C16: 计划 (在什么知识点上还需要更多练习/讲解) | E16: =VLOOKUP(D4,day1!$B$1:$J$85,8,FALSE) -> 动态规划问题的状态转移方程，多做一些dp题目，练习更加熟练推导状态转移方程 | Q16: 学生自我反思 (在测试/学习中出现了什么失误/错误) | T16: 阅读程序： （2）、1（不会）、2（我赌它两行输出相同）、5（因为第一题赌它俩函数输出相同，所以直接拿dp表算的，然后就错了） （3）、3（没算对）、4（没算对）
B18: 教师寄语 | C18: =VLOOKUP(D4,day1!$B$1:$Z$85,9,FALSE) -> 今天主要复习了提高组的算法模板，先讲解了各类模板的基础功能，再结合实例分析了它们在实际问题中的运用技巧。熊子轩同学对模板的理解比较到位，在课堂中能灵活选用与组合，思路清晰，条理分明，能够针对不同题型提出恰当的算法方案。在测试中，他能迅速将常用模板应用到具体题目中，代码编写稳健，整体表现积极。 不过在模板题部分，有一道题因细节处理不够严谨而失分较多；而在思维题部分，他采用了多道题的暴力解法，虽然没有完全解出最优解，但也凭借这种策略拿到了可观的分数。若能在细节检查上更加严谨，并在思维题中多尝试优化思路，成绩还有进一步提升的空间。
Q20: 计划 (在什么知识点上还需要更多练习/讲解) | T20: 树、图、动态规划
P22: 教师寄语 | Q22: 今天的课程内容是一次初赛模拟赛和讲解，以及2022年真题的测试与讲解。今天陈曦的表现很不错，超过了浙江晋级分数线整整10分，在基础选择和完善代码部分都是满分，这个成绩已经非常不错了。明天我们会把所有J组的知识点再过一遍，做最后一遍查漏补缺，最后做一下2023的真题卷，作为我们集训营内容的收尾，希望陈曦可以在明天也可以获得一个好成绩。
A25: 王成峰寒假集训学习反馈卡
C29: 今日知识点 | E29: =$G$6 -> 0
C30: 课堂积极性 | E30: 代码完成速度 | G30: 每日测试成绩 | I30: 综合评价
C32: A | E32: A | G32: A+ | I32: A
C36: 学生总结 | D36: 收获 (今天学到了/回忆起了什么知识) | F36: 今天增强巩固了二分答案，增强了对二分答案的应用，进行了模拟来解决问题，比如区间二分答案的模拟。 还有一些二分答案的小技巧，比如在模拟二分答案时，要认真审题，理解题目想让我们做的事是什么，然后可以对于一些复杂的代码进行一些简化和优化，这样反而可以增强代码的准确性。
D38: 反思 (在测试/学习中出现了什么失误/错误) | F38: 在考试时，对于解题过程复杂繁琐的题，解题过程的分析还需更加仔细，不然会发生一些不仔细的小错误。
C40: 教师寄语 | D40: 今天是成峰在二分算法的最后一课，今天的题目会更加地综合，更考验成峰的代码实现能力。现在二分算法的问题思想成峰已经理解地非常深刻了，能够在对应的问题中使用这个算法。代码实现的基本功还是有待提高，在实现时，会在一些地方会出些小错误。在寒假后的春季课程中，建议加强中等难度的模拟类问题的训练，可以获得更好的效果。

Sheet day2
B1: 姓名 | C1: 课堂表现 | D1: 代码能力 | E1: 理解能力 | F1: 综合评价 | G1: 总结 | H1: 反思 | I1: 计划 | J1: 反馈结果 | K1: 总评 | L1: 课堂表现 | M1: 理解能力 | N1: 代码能力 | O1: 后续建议
A2: 今天重点讲解了种常见的数据结构在动态规划状态转移中的加速技巧，以及讲解了昨天的 atcoder 的比赛。 | B2: 葛义 | C2: B | D2: C+ | E2: C | F2: A- | J2: =A$2&""&SUBSTITUTE(IF(OR(C2="A",C2="A-",C2="A+"),L$2,IF(OR(C2="B",C2="B-",C2="B+"),L$3,L$4)),"【xx】",B2)&"在测试中，"&SUBSTITUTE(IF(OR(D2="A",D2="A-",D2="A+"),N$2,IF(OR(D2="B",D2="B-",D2="B+"),N$3,N$4)),"【xx】",B2)&"在代码方面，"&SUBSTITUTE(IF(OR(E2="A",E2="A-",E2="A+"),M$2,IF(OR(E2="B",E2="B-",E2="B+"),M$3,M$4)),"【xx】",B2)&""&SUBSTITUTE(IF(OR(F2="A",F2="A-",F2="A+"),O$2,IF(OR(F2="B",F2="B-",F2="B+"),O$3,O$4)),"【xx】",B2) -> 今天重点讲解了种常见的数据结构在动态规划状态转移中的加速技巧，以及讲解了昨天的 atcoder 的比赛。葛义同学在昨天的Atcoder 中表现不错，能够做出基础的题目，并且在老师讲解后能够及时进行补题，对于较难的题目也有很好的探究精神，对于早上讲解的动态规划问题，孩子也能及时想到朴素的转移方程，在老师讲解后能够理解优化转移的技巧。在测试中，在代码方面，在代码方面，葛义在 dp 测试中可以结合 dfs 枚举的方式来获取部分分，但是在设计 dp 状态方面还不够熟悉，在做题目时还是需要多考虑一些特殊的情况，去设计状态，我们会在后续加强孩子对于基础动态规划的练习，在实战中真正运用动态规划的思想。 | K2: =IF(D2="A",1,0)*30+IF(D2="B",1,0)*20+IF(D2="C",1,0)*10+IF(E2="A",1,0)*30+IF(E2="B",1,0)*20+IF(E2="C",1,0)*10+IF(F2="A",1,0)*30+IF(F2="B",1,0)*20+IF(F2="C",1,0)*10 -> 10 | L2: 【xx】同学在昨天的Atcoder 中表现非常不错，并且在老师讲解后能够及时进行补题，对于较难的题目也有很好的探究精神，对于早上讲解的动态规划问题，孩子也能及时想到朴素的转移方程，并且在老师的引导下能够想到优化转移的办法。 | M2: 【xx】在 dp 测试中能够在题目中写出最基本的动态规划式子，同时可以结合 dfs 枚举的方式来获取部分分，但是在优化方面还不够熟悉，在做题目时还是需要多考虑一些特殊的情况，去优化状态或者转移的时间。 | N2: 【xx】在今天的模版练习中，基本上把考试的模版都写出来了，非常不错。
L3: 【xx】同学在昨天的Atcoder 中表现不错，能够做出基础的题目，并且在老师讲解后能够及时进行补题，对于较难的题目也有很好的探究精神，对于早上讲解的动态规划问题，孩子也能及时想到朴素的转移方程，在老师讲解后能够理解优化转移的技巧。 | M3: 【xx】在 dp 测试中能够在题目中写出最基本的动态规划式子，但是在优化方面还不够熟悉，在做题目时还是需要多考虑一些特殊的情况，去优化状态或者转移的时间，我们会在后续督促孩子多做练习，加强对于知识点的实际运用能力。 | N3: 【xx】在今天的模版练习中，【xx】对于 dp 的模版掌握的不错，基本都能写对，但是对于其他的一些模版【xx】 掌握的还是有些欠缺。【xx】非常好学，在吃好晚饭后，孩子主动回到教室练习模版，非常不错。 | O3: 我们会在后续督促孩子多做练习，加强对于知识点的实际运用能力。
M4: 在代码方面，【xx】在 dp 测试中可以结合 dfs 枚举的方式来获取部分分，但是在设计 dp 状态方面还不够熟悉，在做题目时还是需要多考虑一些特殊的情况，去设计状态，我们会在后续加强孩子对于基础动态规划的练习，在实战中真正运用动态规划的思想。 | O4: 我们会在后续加强孩子对于基础动态规划以及数据结构的练习，在实战中真正运用动态规划的思想。
B7: 祁靖轩 | C7: A- | D7: A | E7: A | F7: A+ | G7: 今天的任务就是深入学习了dp,上午主要研究dp状态设计(数组的意义)及状态转移的方法,回顾了不同种类的dp,简单了解了dp优化的概念(主要为数据结构的优化).而下午针对dp进行了专项测试,晚上讲解了测试题,题目难度很高但老师讲的很细致,让我受益匪浅. | H7: 在考试时,一些高难题没有骗到分,虽然部分题是真的完成不了其子任务,但还是有些遗憾. | I7: dp数组的状态设计,以及怎么识别一些dp题应该要用dp. | J7: 今天重点讲解了种常见的数据结构在动态规划状态转移中的加速技巧。对于早上讲解的动态规划问题，靖轩也能及时想到朴素的转移方程，在老师讲解后能够理解优化转移的技巧。靖轩在今天的模版练习中，基本上把考试的模版都写出来了，非常不错。在代码方面，靖轩在 dp 测试中能够在题目中写出最基本的动态规划式子，并且成功通过了两道题，不过在其他题目时，在设计 dp 状态上会出现问题，不过这也是正常现象，我们会在后续有相关的练习，加强对于知识点的实际运用能力。 | L7: 今天重点讲解了种常见的数据结构在动态规划状态转移中的加速技巧，以及讲解了昨天的 atcoder 的比赛。沈奕同学在昨天的Atcoder 中表现不错，能够做出基础的题目，并且在老师讲解后能够及时进行补题，对于较难的题目也有很好的探究精神，对于早上讲解的动态规划问题，孩子也能及时想到朴素的转移方程，在老师讲解后能够理解优化转移的技巧。沈奕在今天的模版练习中，基本上把考试的模版都写出来了，非常不错。在代码方面，沈奕在 dp 测试中能够在题目中写出最基本的动态规划式子，但是在优化方面还不够熟悉，在做题目时还是需要多考虑一些特殊的情况，去优化状态或者转移的时间，我们会在后续督促孩子多做练习，加强对于知识点的实际运用能力。
B8: 吴奕淳 | C8: A+ | D8: A+ | E8: A | F8: A+ | G8: 今天学习了状态压缩dp，线性dp，还有区间dp | H8: 在复赛模拟赛中，想不出DP解法，只使用了暴力解法，导致没有完全通过。同时，由于拓展欧几里得算法不熟练，在比赛中没有写出来，导致没有通过。 | I8: 应多默写几遍拓展欧几里得算法，增强记忆；同时多练习dp相关题目，提高代码熟练度。 | J8: 今天重点讲解了种常见的数据结构在动态规划状态转移中的加速技巧。对于早上讲解的动态规划问题，奕淳也能及时想到朴素的转移方程，在老师的引导下能够想到优化转移的办法。奕淳在今天的比赛中发挥不错，基本上把考试的模版都写出来了，非常不错。在代码方面，奕淳在 dp 测试中能够在题目中写出最基本的动态规划式子，并且能过通过一道较难的题目，同时可以结合 dfs 枚举的方式来获取部分分，但是在优化方面还不够熟悉，在做题目时还是需要多考虑一些特殊的情况，去优化状态或者转移的时间。 | L8: 今天重点讲解了种常见的数据结构在动态规划状态转移中的加速技巧，以及讲解了昨天的 atcoder 的比赛。煜涵同学在昨天的Atcoder 中表现非常不错，能自己独立做出一道非常困难的题目，并且在老师讲解后能够及时进行补题，对于较难的题目也有很好的探究精神，对于早上讲解的动态规划问题，孩子也能及时想到朴素的转移方程，并且在老师的引导下能够想到优化转移的办法。煜涵在今天的模版练习中，基本上把考试的模版都写出来了，非常不错。在代码方面，煜涵在 dp 测试中能够在题目中写出最基本的动态规划式子，同时可以结合 dfs 枚举的方式来获取部分分，但是在优化方面还不够熟悉，在做题目时还是需要多考虑一些特殊的情况，去优化状态或者转移的时间。
B9: 张允泽 | C9: A | D9: A | E9: A | F9: A | G9: 今天复习了传统的线性，二维，多维dp，继续深入地学习了状态压缩dp，单调栈优化dp，树状数组优化dp，以及其他有关于动态规划的知识。 | H9: 测试时T10一开始没读完题就开始写，写完发现方向错了，对着题目条件死磕了40多分钟，最后还没有解决问题，浪费了许多时间。 | I9: 还是要继续深入学习动态规划问题，在做题时能够快速捕捉到题目的要点以设计状态，转移状态，快速求解问题等 ， 测试时合理分配时间，不要再一些题目上浪费过多时间。 | J9: 今天重点讲解了种常见的数据结构在动态规划状态转移中的加速技巧。对于早上讲解的动态规划问题，允泽也能及时想到朴素的转移方程，并且在老师的引导下能够想到优化转移的办法。允泽在今天的比赛中发挥不错，基本上把考试的模版都写出来了，非常不错。在代码方面，允泽在 dp 测试中能够在题目中写出最基本的动态规划式子，并且能想到通过背包来解决问题，允泽在状态设计上做的非常不错，但是在发现正解不会做的时候，可以通过去做部分分来获取一定的分数，这块下次可以注意下。 | L9: 今天重点讲解了种常见的数据结构在动态规划状态转移中的加速技巧，以及讲解了昨天的 atcoder 的比赛。煜琦同学在昨天的Atcoder 中表现非常不错，并且在老师讲解后能够及时进行补题，对于较难的题目也有很好的探究精神，对于早上讲解的动态规划问题，孩子也能及时想到朴素的转移方程，并且在老师的引导下能够想到优化转移的办法。煜琦在今天的模版练习中，基本上把考试的模版都写出来了，非常不错。在代码方面，煜琦在 dp 测试中能够在题目中写出最基本的动态规划式子，但是在优化方面还不够熟悉，在做题目时还是需要多考虑一些特殊的情况，去优化状态或者转移的时间，我们会在后续督促孩子多做练习，加强对于知识点的实际运用能力。
B10: 陈一实 | C10: A | D10: A+ | E10: A- | F10: A | G10: 介绍动态规划（Dynamic Programming, DP）及其解决的问题、根据其设计的算法及优化。 动态规划是一种通过把原问题分解为相对简单的子问题的方式求解复杂问题的方法。 | H10: 对于一个能用动态规划解决的问题，一般采用如下思路解决： 1将原问题划分为若干 阶段，每个阶段对应若干个子问题，提取这些子问题的特征（称之为 状态）； 2寻找每一个状态的可能 决策，或者说是各状态间的相互转移方式（用数学的语言描述就是 状态转移方程）。 3按顺序求解每一个阶段的问题 | I10: DP 优化， 所谓 DP 优化，是指许多动态规划问题虽然容易列出朴素的状态转移方程，但直接计算往往效率低下，因此需要借助一些技巧来降低时间复杂度。 | J10: 今天重点讲解了种常见的数据结构在动态规划状态转移中的加速技巧。对于早上讲解的动态规划问题，一实也能及时想到朴素的转移方程，并且在老师的引导下能够想到优化转移的办法。一实在今天的比赛中发挥不错，基本上把考试的模版都写出来了，非常不错。在代码方面，一实可以结合 dfs 枚举的方式来获取部分分，但是在优化方面还不够熟悉，在做题目时还是需要多考虑一些特殊的情况，去优化状态或者转移的时间，我们会在后续有相关的练习，加强对于知识点的实际运用能力。 | L10: 今天重点讲解了种常见的数据结构在动态规划状态转移中的加速技巧，以及讲解了昨天的 atcoder 的比赛。钧维同学在昨天的Atcoder 中是班里考的最好的，非常厉害，对于早上讲解的动态规划问题，孩子也能及时想到朴素的转移方程，并且在老师的引导下能够想到优化转移的办法。钧维在今天的模版练习中，基本上把考试的模版都写出来了。在代码方面，钧维在 dp 测试中能够在题目中写出朴素的动态规划式子，同时可以在代码的基础上进行优化，非常不错，继续保持。
B11: 余廷锴 | C11: A- | D11: A- | E11: A- | F11: A | G11: 学习了有关于dp的知识，学习了多种dp类型，如背包dp；状态压缩DP；区间DP等，练习了dp题目，复习了部分代码模板。 | H11: 在做动态规划的题目中，设计不出状态与状态转移方程，只能通过暴力获得部分分。 | I11: 练习DP题目，设计状态与状态转移方程，练习观察力，数学变换能力，找到设计状态的灵感。 | J11: 今天重点讲解了种常见的数据结构在动态规划状态转移中的加速技巧。对于早上讲解的动态规划问题，廷锴也能及时想到朴素的转移方程，并且在老师的引导下能够想到优化转移的办法。廷锴在今天的比赛中发挥不错，基本上把考试的模版都写出来了，非常不错。在代码方面，廷锴可以结合 dfs 枚举的方式来获取部分分，但是在优化方面还不够熟悉，在做题目时还是需要多考虑一些特殊的情况，去优化状态或者转移的时间，我们会在后续有相关的练习，加强对于知识点的实际运用能力。 | L11: 今天重点讲解了种常见的数据结构在动态规划状态转移中的加速技巧，以及讲解了昨天的 atcoder 的比赛。谨泽同学在昨天的Atcoder 中表现不错，能够做出基础的题目，并且在老师讲解后能够及时进行补题，对于较难的题目也有很好的探究精神，对于早上讲解的动态规划问题，孩子也能及时想到朴素的转移方程，在老师讲解后能够理解优化转移的技巧。谨泽在今天的模版练习中，基本上把考试的模版都写出来了，非常不错。在代码方面，谨泽在 dp 测试中能够在题目中写出最基本的动态规划式子，但是在优化方面还不够熟悉，在做题目时还是需要多考虑一些特殊的情况，去优化状态或者转移的时间，我们会在后续督促孩子多做练习，加强对于知识点的实际运用能力。我们会在后续督促孩子多做练习，加强对于知识点的实际运用能力。
B12: 邓宇然 | C12: A- | D12: A- | E12: A- | F12: A- | G12: 今天学习了状态压缩动态规划，线性动态规划，区间动态规划 ；CSP复赛不可使用#define int long long | H12: 在复赛模拟赛中，出现了动态规划无法正确定义数组状态，同时导致找不到动态转移方程的情况。也有因想不出动态规划解法而导致的Time Limit enough；忘记了拓展欧几里得的算法 | I12: 多练习练习动态规划题目，找到定义数组状态的逻辑；记背拓展欧几里得代码模板 | J12: 今天重点讲解了种常见的数据结构在动态规划状态转移中的加速技巧。对于早上讲解的动态规划问题，宇然也能及时想到朴素的转移方程，并且在老师的引导下能够想到优化转移的办法。宇然在今天的比赛中发挥非常不错，基本上把考试的模版都写出来了，非常不错。在代码方面，宇然可以结合 dfs 枚举的方式来获取部分分，但是在优化方面还不够熟悉，在做题目时还是需要多考虑一些特殊的情况，去优化状态或者转移的时间，我们会在后续有相关的练习，加强对于知识点的实际运用能力，继续加油。 | L12: 今天重点讲解了种常见的数据结构在动态规划状态转移中的加速技巧，以及讲解了昨天的 atcoder 的比赛。恺睿同学在昨天的Atcoder 中表现不错，能够做出基础的题目，并且在老师讲解后能够及时进行补题，对于较难的题目也有很好的探究精神，对于早上讲解的动态规划问题，孩子也能及时想到朴素的转移方程，在老师讲解后能够理解优化转移的技巧。恺睿在今天的模版练习中，基本上把考试的模版都写出来了，非常不错。在代码方面，恺睿在 dp 测试中能够在题目中成功做出一道很难的题目，非常不错，但是因为时间原因，没有去做剩下的题目，考试的时候需要注意控制时间。
B13: 张世昌 | C13: A- | D13: A- | E13: A- | F13: A- | G13: 在刘老师的坚定带领下，在张老师的辛勤辅助下，今天我们深度学习了有关DP的知识，知道了更多类型的DP，比如：背包 DP、区间 DP、DAG 上的 DP、树形 DP、换根DP、状压 DP、数位 DP、计数 DP、动态 DP、概率 DP、记忆化搜索等，还接触到了一些申必优化DP的方法，比如：单调队列/单调栈优化、斜率优化、四边形不等式优化、Slope Trick 优化、WQS二分、状态设计优化，今天收获最多的就是下午考试时的题，经过刘老师的耐心教导下，又学习到了写DP题目的方法，收获很多。 | H13: 在下午的考试中，有DP的题没有推出来DP状态转移方程，没有设计好DP，导致只能拿部分分（骗分）。 | I13: 我还要多深度练习DP题目，找到设计DP和设计状态转移方程的灵感。 | J13: 今天重点讲解了种常见的数据结构在动态规划状态转移中的加速技巧。对于早上讲解的动态规划问题，世昌也能及时想到朴素的转移方程，在老师讲解后能够理解优化转移的技巧。世昌在今天的比赛中发挥非常不错，基本上把考试的模版都写出来了。在代码方面，世昌在 dp 测试中能够在题目中写出最基本的动态规划式子，但是在优化方面还不够熟悉，在做题目时还是需要多考虑一些特殊的情况，去优化状态或者转移的时间，我们会在后续督促孩子多做练习，加强对于知识点的实际运用能力。 | L13: 今天重点讲解了种常见的数据结构在动态规划状态转移中的加速技巧，以及讲解了昨天的 atcoder 的比赛。天翊同学在昨天的Atcoder 中表现非常不错，能自己做出一道较为困难的题，并且在老师讲解后能够及时进行补题，对于较难的题目也有很好的探究精神，对于早上讲解的动态规划问题，孩子也能及时想到朴素的转移方程，并且在老师的引导下能够想到优化转移的办法。在测试中，天翊在今天的模版练习中，天翊对于 dp 的模版掌握的不错，基本都能写对，但是对于其他的一些模版天翊 掌握的还是有些欠缺。天翊非常好学，在吃好晚饭后，孩子主动回到教室练习模版，非常不错。在代码方面，天翊在 dp 测试中能够在题目中成功做出一道很难的题目，同时可以结合 dfs 枚举的方式来获取部分分，但是在优化方面还不够熟悉，在做题目时还是需要多考虑一些特殊的情况，去优化状态或者转移的时间。
B14: 张梓涵 | C14: A- | D14: A- | E14: A- | F14: A- | G14: 今天我们上午整个的学习了一下DP的大体内容并理了一下优化DP的思路，下午我们考了三个多小时，后面四题DP题一道都没做出来，晚上讲了后面三题的思路及代码怎么写 | H14: 在考试中因为太想拿满倒数第二题，导致没什么时间拿全部分分，但整体来说是尽力了，只是在设计状态时，没有想到多开几个状态的方案，对于一些与数学有关的题意没有理解太透彻 | I14: 在讲解DP状态设计时没有太理解透如何想出的状态设计，如括号序列 | J14: 今天的课程围绕动态规划的转移优化展开，重点讲解了单调数据结构优化转移、优先队列优化转移以及利用多种数据结构提升转移效率的技巧。梓涵能够较好地跟随授课思路，积极参与课堂交流，对核心概念的理解基本到位。在代码能力方面，梓涵能完成基础 DP 的实现，但在将数据结构与动态规划相结合的细节处理、边界条件判断及效率优化上仍有提升空间。梓涵在今天的比赛中发挥非常不错，基本上把考试的模版都写出来了，说明对主要知识点掌握较好，但在应对困难的 dp 问题时的思路拓展与实现熟练度还有待加强。我们会在后续督促孩子多做练习，加强对于知识点的实际运用能力。 | L14: 今天重点讲解了种常见的数据结构在动态规划状态转移中的加速技巧，以及讲解了昨天的 atcoder 的比赛。震轩同学在昨天的Atcoder 中表现不错，能够做出基础的题目，并且在老师讲解后能够及时进行补题，对于较难的题目也有很好的探究精神，对于早上讲解的动态规划问题，孩子也能及时想到朴素的转移方程，在老师讲解后能够理解优化转移的技巧。在模版测试中，震轩在今天的模版练习中，震轩对于 dp 的模版掌握的不错，基本都能写对，但是对于其他的一些模版震轩 掌握的还是有些欠缺。震轩非常好学，在吃好晚饭后，孩子主动回到教室练习模版，非常不错。在代码方面，震轩在 dp 测试中能够在题目中写出最基本的动态规划式子，但是在优化方面还不够熟悉，在做题目时还是需要多考虑一些特殊的情况，去优化状态或者转移的时间，我们会在后续督促孩子多做练习，加强对于知识点的实际运用能力。我们会在后续督促孩子多做练习，加强对于知识点的实际运用能力。
B15: 杜星澎 | C15: A- | D15: A- | E15: A- | F15: A- | G15: 知识巩固：无； 新知学习：二维DP、多维DP、状压DP、背包DP、数据结构优化DP。 | H15: T1exgcd板子学了忘忘了学，以前总是学不会，今天终于理解了； T7一开始考虑正难则反，状态设计少了一维，导致转移方程有误，只能骗分35pts； T8、T9、T11DP都只有一个一个大概的思路，转移方程没有想到，只能去暴力了（T8和T11甚至都没骗到分）； T10有一个大概的思路，但是考虑的是将整个矩阵分为上下两个三角形，做一遍数字金字塔，再把两部分的最大值加起来，得到答案，但是主对角线有可能被两部分重叠计算，与题意不符。 | I15: 背包 DP、区间 DP、DAG 上的 DP、树形 DP、状压 DP、数位 DP、插头 DP、计数 DP、动态 DP、概率 DP、DP 套 DP、DP 优化（好吧，其实我每一种DP都挺菜的）。 | J15: 今天的课程围绕动态规划的转移优化展开，重点介绍了单调数据结构优化转移、优先队列优化转移以及利用多种数据结构提升转移效率的技巧。星澎能够认真跟随授课内容，在关键知识点处积极思考并适时参与讨论，理解较为到位。星澎编程基础扎实，能够熟练将所学算法思想实现为高效、准确的程序，并能在实现过程中兼顾边界处理与性能优化。星澎在今天的比赛中发挥非常不错，基本上把考试的模版都写出来了，说明对主要知识点掌握较好，但在应对困难的 dp 问题时的思路拓展与实现熟练度还有待加强。我们会在后续督促孩子多做练习，加强对于知识点的实际运用能力。 | L15: 今天重点讲解了种常见的数据结构在动态规划状态转移中的加速技巧，以及讲解了昨天的 atcoder 的比赛。嘉润同学在昨天的Atcoder 中表现不错，能够做出基础的题目，并且在老师讲解后能够及时进行补题，对于较难的题目也有很好的探究精神，对于早上讲解的动态规划问题，孩子也能及时想到朴素的转移方程，在老师讲解后能够理解优化转移的技巧。嘉润在今天的模版练习中，嘉润对于 dp 的模版掌握的不错，基本都能写对，但是对于其他的一些模版嘉润 掌握的还是有些欠缺。嘉润非常好学，在吃好晚饭后，孩子主动回到教室练习模版，非常不错。在代码方面，在代码方面，嘉润在 dp 测试中可以结合 dfs 枚举的方式来获取部分分，但是在设计 dp 状态方面还不够熟悉，在做题目时还是需要多考虑一些特殊的情况，去设计状态，我们会在后续加强孩子对于基础动态规划的练习，在实战中真正运用动态规划的思想。
B16: 熊子轩 | C16: A- | D16: B+ | E16: B+ | F16: A- | G16: 学习了dp知识，上午讲解到了一道dp例题，下午进行测试后对几道题目进行了讲解，学习了如何对dp进行优化 讲解了如何得到dp思路及推出递推方程 | H16: 测试中在一道题上面耗费了较多时间，导致后面的题目部分分没有得到 | I16: 我要对dp题目进行跟多练习 | J16: 今天的课程围绕动态规划的转移优化展开，重点讲解了单调数据结构优化转移、优先队列优化转移以及利用多种数据结构提升转移效率的技巧。子轩能够较好地跟随授课内容，认真听讲并在讨论环节中适时表达自己的思路，对核心知识点理解较为扎实。子轩能够完成基础 DP 的实现，但在数据结构与 DP 结合的优化细节、边界条件处理以及代码效率上仍有提升空间。子轩在今天的比赛中发挥非常不错，基本上把考试的模版都写出来了，说明对主要知识点掌握较好，但在应对困难的 dp 问题时的思路拓展与实现熟练度还有待加强。我们会在后续督促孩子多做练习，加强对于知识点的实际运用能力。 | L16: 今天重点讲解了种常见的数据结构在动态规划状态转移中的加速技巧，以及讲解了昨天的 atcoder 的比赛。宇轩同学在昨天的Atcoder 中表现不错，能够做出基础的题目，并且在老师讲解后能够及时进行补题，对于较难的题目也有很好的探究精神，对于早上讲解的动态规划问题，孩子也能及时想到朴素的转移方程，在老师讲解后能够理解优化转移的技巧。在模版测试中，宇轩在今天的模版练习中，宇轩对于 dp 的模版掌握的不错，基本都能写对，但是对于其他的一些模版宇轩 掌握的还是有些欠缺。宇轩非常好学，在吃好晚饭后，孩子主动回到教室练习模版，有问题也会及时询问老师。在代码方面，在代码方面，宇轩在 dp 测试中可以结合 dfs 枚举的方式来获取部分分，但是在设计 dp 状态方面还不够熟悉，在做题目时还是需要多考虑一些特殊的情况，去设计状态，我们会在后续加强孩子对于基础动态规划的练习，在实战中真正运用动态规划的思想。我们会在后续督促孩子多做练习，加强对于知识点的实际运用能力。
B17: 金智宸 | C17: A- | D17: B+ | E17: B+ | F17: B+ | G17: 很多很多关于dp的知识 | H17: 没有想出如何设计dp的状态和方程；盯一道题盯了太久，没有合理分配时间去做其他题，没有注意一些细节。 | I17: 多了解 dp的状态(转移方程)是怎么设计出来的，多注意点细节。 | J17: 今天的课程围绕动态规划的转移优化展开，重点讲解了单调数据结构优化转移、优先队列优化转移以及利用数据结构提升转移效率的方法。智宸能够较好地跟随讲解思路，认真听讲并适时参与讨论，对课程核心概念理解较为扎实。智宸能够完成基础 DP 的实现，但在将数据结构与动态规划结合进行优化、处理复杂边界条件以及提升代码效率方面仍有提升空间。智宸在今天的比赛中发挥非常不错，基本上把考试的模版都写出来了，说明对主要知识点掌握较好，但在应对困难的 dp 问题时的思路拓展与实现熟练度还有待加强。我们会在后续督促孩子多做练习，加强对于知识点的实际运用能力。 | L17: 今天重点讲解了种常见的数据结构在动态规划状态转移中的加速技巧，以及讲解了昨天的 atcoder 的比赛。涵语同学在昨天的Atcoder 中表现不错，能够做出基础的题目，并且在老师讲解后能够及时进行补题，对于较难的题目也有很好的探究精神，对于早上讲解的动态规划问题，孩子也能及时想到朴素的转移方程，在老师讲解后能够理解优化转移的技巧。在模版测试中，涵语在今天的模版练习中，涵语对于 dp 的模版掌握的不错，基本都能写对，但是对于其他的一些模版涵语 掌握的还是有些欠缺。涵语非常好学，在吃好晚饭后，孩子主动回到教室练习模版，非常不错。在代码方面，在代码方面，涵语在 dp 测试中可以结合 dfs 枚举的方式来获取部分分，但是在设计 dp 状态方面还不够熟悉，在做题目时还是需要多考虑一些特殊的情况，去设计状态，我们会在后续加强孩子对于基础动态规划的练习，在实战中真正运用动态规划的思想。
B18: 刘孟霖 | C18: A- | D18: B+ | E18: B+ | F18: B+ | G18: 学习了动态规划的各种相关知识，比如：状态压缩动态规划，单调栈/单调队列优化动态规划 | H18: 在做“货币系统”时因为没看懂题目的意思导致没有通过；在做“Bill的跳转”时因为没有读懂题目意思导致没有通过；在做“最长公共子序列”的时候因为忘记怎么做了导致没有通过。 | I18: 后续计划：多做一些动态规划相关的题目加深对算法的理解；多默写几次一元二次不定式模板；复习动态规划的优化和动态规划的设计 | J18: 今天的课程围绕动态规划的转移优化展开，重点讲解了单调数据结构优化转移、优先队列优化转移以及利用多种数据结构提升转移效率的方法。孟霖能够认真跟随授课内容，适时参与讨论，对核心概念理解较为清晰。同时孟霖能够完成基础 DP 的实现，但在将数据结构与动态规划结合进行优化、处理复杂边界条件以及提升代码效率上仍有一定提升空间。孟霖在今天的比赛中发挥非常不错，基本上把考试的模版都写出来了，说明对主要知识点掌握较好，但在应对困难的 dp 问题时的思路拓展与实现熟练度还有待加强。我们会在后续督促孩子多做练习，加强对于知识点的实际运用能力。 | L18: 今天重点讲解了种常见的数据结构在动态规划状态转移中的加速技巧，以及讲解了昨天的 atcoder 的比赛。可馨同学在昨天的Atcoder 中表现非常不错，能自己做出一道代码实现非常困难的题，并且在老师讲解后能够及时进行补题，对于较难的题目也有很好的探究精神，对于早上讲解的动态规划问题，孩子也能及时想到朴素的转移方程，并且在老师的引导下能够想到优化转移的办法。在模版测试中，可馨在今天的模版练习中，基本上把考试的模版都写出来了，非常不错。在代码方面，可馨在 dp 测试中能够在题目中写出最基本的动态规划式子，但是在优化方面还不够熟悉，在做题目时还是需要多考虑一些特殊的情况，去优化状态或者转移的时间，我们会在后续督促孩子多做练习，加强对于知识点的实际运用能力。
B19: 何奇阳 | C19: A- | D19: A- | E19: A | F19: A | G19: 学了各种各样的dp以及其优化(晕) 学会很多类特定问题的解法 | H19: 手动放弃全部模板题目，去死磕dp，然后前面没得几分，后面也没得几分 写暴力没有决心，总是试图想出dp法然后不幸失败 | I19: 暴力算法需要熟悉，exgcd等模板需要熟练，至于dp……这方面只能说路漫漫其修远兮…… | J19: 今天重点讲解了种常见的数据结构在动态规划状态转移中的加速技巧。对于较难的题目也有很好的探究精神，对于早上讲解的动态规划问题，奇阳也能及时想到朴素的转移方程，并且在老师的引导下能够想到优化转移的办法。在测试中，奇阳今天的模版练习中，奇阳对于 dp 的模版掌握的不错，基本都能写对，但是对于其他的一些模版奇阳 掌握的还是有些欠缺。在代码方面，奇阳在 dp 测试中能够在题目中成功做出两道道很难的题目，非常厉害，同时可以结合 dfs 枚举的方式来获取部分分，但是在优化方面还不够熟悉，在做题目时还是需要多考虑一些特殊的情况，去优化状态或者转移的时间。 | L19: 今天重点讲解了种常见的数据结构在动态规划状态转移中的加速技巧，以及讲解了昨天的 atcoder 的比赛。葛义同学在昨天的Atcoder 中表现不错，能够做出基础的题目，并且在老师讲解后能够及时进行补题，对于较难的题目也有很好的探究精神。在代码方面，葛义对设计 dp 状态方面还不够熟悉，在做题目时还是需要多考虑一些特殊的情况，去设计状态，我们会在后续加强孩子对于基础动态规划的练习，在实战中真正运用动态规划的思想。
B20: 练皓文 | C20: A- | D20: B+ | E20: B+ | F20: B | G20: 学到了各种不同的DP，并做了复赛的题目，回忆了单调队列、最小生成树、状压DP等代码，练习了DP的各种题目。 | H20: 在测试中，对于exgcd等代码不够熟悉，导致没有写出来。同时，对于DP的状态设计能力不够，注意力以及观察力欠佳，导致后面几道DP的练习都没有通过。 | I20: 要多做有关各种DP的题目，锻炼自己的状态设计能力，提升观察力，增加写代码的熟练度；多默写exgcd等代码的模板，增加代码理解，提升熟练度。 | J20: 今天的课程重点讲解了动态规划的转移优化方法，包括单调数据结构优化转移、优先队列优化转移以及数据结构在动态规划中的应用。皓文能够积极跟随讲解并参与讨论，显示出较好的学习主动性。同时皓文能够完成动态规划及基础优化转移算法的实现，但在处理复杂边界条件和提升代码效率方面仍有提升空间。在今天的测试中，皓文对于 dp 的模版掌握的不错，基本都能写对，但是对于其他的一些模版皓文掌握的还是有些欠缺，在面对高难度或综合性问题时思路拓展和细节优化仍需加强。我们会在后续督促孩子多做练习，加强对于知识点的实际运用能力。
B21: 张岳琳 | C21: A- | D21: B+ | E21: B+ | F21: B | G21: 今天回忆起了dp（区间、状压、背包、多维等）、dp优化（单调栈等） | H21: 第8题理解错题意导致做错；多道题没把握好时间导致没时间思考后面的题 | I21: 多练习动态规划问题，以后考试按时间合理分配时间，不在一题上浪费太多时间 | J21: 今天的课程重点讲解了动态规划的转移优化方法，包括单调数据结构优化转移、优先队列优化转移以及数据结构在动态规划中的应用。岳琳能够积极跟随讲解并参与讨论，显示出较好的学习主动性。同时岳琳能够完成动态规划及基础优化转移算法的实现，但在处理复杂边界条件和提升代码效率方面仍有提升空间。在今天的测试中，岳琳对于 dp 的模版掌握的不错，基本都能写对，但是对于其他的一些模版皓文掌握的还是有些欠缺，在面对高难度或综合性问题时思路拓展和细节优化仍需加强。同时在时间分配上也需要注意，不要在同一道题上卡死，继续加油。
B22: 郭维皓 | C22: A- | D22: B+ | E22: B+ | F22: B+ | G22: 记忆化搜索，背包 DP，区间 DP，树形 DP，状压 DP，单调队列/单调栈优化DP | H22: 关于DP设计与exgcd算法掌握的现状反思 最近在算法练习中遇到了明显的瓶颈。动态规划(DP)部分始终难以突破设计关，面对新问题时常常陷入状态定义的迷茫。具体表现为： 无法准确识别子问题结构 状态转移方程推导耗时过长 边界条件处理经常遗漏 而在数论算法的exgcd（扩展欧几里得算法）实现中 对递归终止条件的理解不够直观 | I22: 多练习一些DP题目，多写几次exgcd | J22: 今天重点讲解了种常见的数据结构在动态规划状态转移中的加速技巧。对于较难的题目也有很好的探究精神，对于早上讲解的动态规划问题，维皓也能及时想到朴素的转移方程，在老师讲解后能够理解优化转移的技巧。在模版测试中，维皓在今天的模版练习中，涵语对于 dp 的模版掌握的不错，基本都能写对，但是对于其他的一些模版维皓 掌握的还是有些欠缺。在代码方面，维皓在在面对高难度或综合性问题时思路拓展和细节优化仍需加强，在做题目时还是需要多考虑一些特殊的情况，去设计状态，我们会在后续加强孩子对于基础动态规划的练习，在实战中真正运用动态规划的思想，继续加油。
A31: 代码能力(当天最难的知识点 或 所有基础都理解就是A 或 班级表现前70%) A / B 理解能力(当天最难的知识点 或 所有基础都理解就是A 或 班级表现前70%) A / B 摸底测或代码模板默写(统称为小检测，4-5-1 对应A-B-C) A:30 B:20 C:10 最终表现 A类 >= 80分 B类 >= 60分 C类 < 60分
A38: 代码能力：取决于今天的模版练习情况和昨天atcdoer C题是否做出的
A39: 理解能力：取决于 atcoder 的 D 是否通过，以及最后 5 题的解题情况

Sheet Day2反馈表
A1: 暑假集训学习反馈卡 | N1: 张陈曦暑假集训学习反馈卡
B4: 姓名 | D4: 郭维皓
P5: 测试内容: CSP2022初赛真题
B6: 课堂积极性 | D6: 理解能力 | F6: 代码能力 | H6: 综合评价 | P6: 基础选择得分 (满分30) | R6: 程序阅读得分 (满分40) | U6: 完善代码得分 (满分30) | W6: 总分 (浙江晋级线78.5)
B8: =VLOOKUP(D4,day2!$B$7:$G$100,2,FALSE) -> A- | D8: =VLOOKUP(D4,day2!$B$7:$G$100,3,FALSE) -> B+ | F8: =VLOOKUP(D4,day2!$B$7:$G$100,4,FALSE) -> B+ | H8: =VLOOKUP(D4,day2!$B$7:$G$100,5,FALSE) -> B+ | P8: 30 | R8: 28.5 | U8: 30 | W8: =SUM(P8:V10) -> 88.5
B12: 学生总结 | C12: 收获 (今天学到了/回忆起了什么知识) | E12: =VLOOKUP(D4,day2!$B$7:$G$100,6,FALSE) -> 记忆化搜索，背包 DP，区间 DP，树形 DP，状压 DP，单调队列/单调栈优化DP | P12: 学生总结 | Q12: 收获 (今天学到了/回忆起了什么知识) | T12: 二分查找、哈夫曼编码
C14: 学生自我反思 (在测试/学习中出现了什么失误/错误) | E14: =VLOOKUP(D4,day2!$B$7:$Z$100,7,FALSE) -> 关于DP设计与exgcd算法掌握的现状反思 最近在算法练习中遇到了明显的瓶颈。动态规划(DP)部分始终难以突破设计关，面对新问题时常常陷入状态定义的迷茫。具体表现为： 无法准确识别子问题结构 状态转移方程推导耗时过长 边界条件处理经常遗漏 而在数论算法的exgcd（扩展欧几里得算法）实现中 对递归终止条件的理解不够直观 | Q14: 学生自我反思 (在测试/学习中出现了什么失误/错误) | T14: 阅读程序： （2）、1（不会）、2（我赌它两行输出相同）、5（因为第一题赌它俩函数输出相同，所以直接拿dp表算的，然后就错了） （3）、3（没算对）、4（没算对）
C16: 计划 (在什么知识点上还需要更多练习/讲解) | E16: =VLOOKUP(D4,day2!$B$7:$Z$100,8,FALSE) -> 多练习一些DP题目，多写几次exgcd | Q16: 计划 (在什么知识点上还需要更多练习/讲解) | T16: 树、图、动态规划
B18: 教师寄语 | C18: =VLOOKUP(D4,day2!$B$7:$Z$100,9,FALSE) -> 今天重点讲解了种常见的数据结构在动态规划状态转移中的加速技巧。对于较难的题目也有很好的探究精神，对于早上讲解的动态规划问题，维皓也能及时想到朴素的转移方程，在老师讲解后能够理解优化转移的技巧。在模版测试中，维皓在今天的模版练习中，涵语对于 dp 的模版掌握的不错，基本都能写对，但是对于其他的一些模版维皓 掌握的还是有些欠缺。在代码方面，维皓在在面对高难度或综合性问题时思路拓展和细节优化仍需加强，在做题目时还是需要多考虑一些特殊的情况，去设计状态，我们会在后续加强孩子对于基础动态规划的练习，在实战中真正运用动态规划的思想，继续加油。 | P18: 教师寄语 | Q18: 今天的课程内容是一次初赛模拟赛和讲解，以及2022年真题的测试与讲解。今天陈曦的表现很不错，超过了浙江晋级分数线整整10分，在基础选择和完善代码部分都是满分，这个成绩已经非常不错了。明天我们会把所有J组的知识点再过一遍，做最后一遍查漏补缺，最后做一下2023的真题卷，作为我们集训营内容的收尾，希望陈曦可以在明天也可以获得一个好成绩。

Sheet day3
A1: 3 | B1: 姓名 | C1: 课堂积极性 | D1: 代码能力 | E1: 理解能力 | F1: 综合评价 | G1: 总结 | H1: 反思 | I1: 计划 | J1: 反馈结果 | K1: 总评 | L1: 课堂积极性 | M1: 理解能力 | N1: 代码能力 | O1: 后续建议
A2: 今天主要选讲了提高组的真题，聚焦在如何从题目中捕捉特殊性质与关键特点，并结合一些“小技巧”来将原本 O(n²) 或更高复杂度的算法调优到 O(n log n) 或 O(n) 级别。 | B2: 葛义 | C2: B- | D2: C+ | E2: C+ | F2: C+ | J2: =A$2&""&SUBSTITUTE(IF(OR(C2="A",C2="A-",C2="A+"),L$2,IF(OR(C2="B",C2="B-",C2="B+"),L$3,L$4)),"【xx】",B2)&"在代码方面，"&SUBSTITUTE(IF(OR(D2="A",D2="A-",D2="A+"),M$2,IF(OR(D2="B",D2="B-",D2="B+"),M$3,M$4)),"【xx】",B2)&"在测试中，"&SUBSTITUTE(IF(OR(E2="A",E2="A-",E2="A+"),N$27,IF(OR(E2="B",E2="B-",E2="B+"),N$28,N$29)),"【xx】",B2)&""&SUBSTITUTE(IF(OR(F2="A",F2="A-",F2="A+"),O$2,IF(OR(F2="B",F2="B-",F2="B+"),O$3,O$4)),"【xx】",B2) -> 今天主要选讲了提高组的真题，聚焦在如何从题目中捕捉特殊性质与关键特点，并结合一些“小技巧”来将原本 O(n²) 或更高复杂度的算法调优到 O(n log n) 或 O(n) 级别。葛义同学能够在老师或同学发起讨论时给予回应，课堂上既认真倾听也适时参与。在代码方面，葛义同学已能意识到从题目中提取关键信息对于算法的重要性，并尝试使用基础的小技巧来缩减常数或降低复杂度。在测试中，葛义通过今天的学习，能够在题目中抓住关键性质，并且在部分代码中使用技巧来提升代码效率，成功写出了压轴题的部分分代码，还是不错的。但是在一道用二分优化的题目中，孩子没想到优化方法，后续需要通过不断练习来提高算法优化技巧的熟练度。后续会通过不断练习来提高算法优化技巧的熟练度。 | K2: =IF(D2="A",1,0)*30+IF(D2="B",1,0)*20+IF(D2="C",1,0)*10+IF(E2="A",1,0)*30+IF(E2="B",1,0)*20+IF(E2="C",1,0)*10+IF(F2="A",1,0)*30+IF(F2="B",1,0)*20+IF(F2="C",1,0)*10 -> 0 | L2: 【xx】同学积极参与课堂互动，对于一些常见的算法优化能够很快的反应出来。 | M2: 【xx】同学表现优异，能够迅速捕捉真题中的关键信息，并灵活运用小技巧将原本较慢的解法优化至更高效的算法，思路清晰。 | N2: 【xx】能够迅速的从题目中抓住关键性质，然后灵活运用技巧将代码的时间复杂度优化到一个可以完全通过题目的程度，成功使用二分做出了一道较难的题目。
L3: 【xx】同学能够在老师或同学发起讨论时给予回应，课堂上既认真倾听也适时参与。 | M3: 【xx】同学基础扎实，对题目特殊性质和优化思路有较好把握，能够在指导下想出核心步骤，但在整体思路与细节实现上还需进一步锻炼。 | N3: 【xx】能够迅速的从题目中抓住关键性质，然后灵活运用技巧将代码的时间复杂度优化到一个可以完全通过题目的程度，成功优化代码通过了一道题目。但是在一道用二分优化的题目中，孩子没想到优化方法，后续需要通过不断练习来提高算法优化技巧的熟练度。 | O3: 后续会通过反思加上总结的方法来锻炼建模能力。
L4: 【xx】同学在课堂上能够专心听讲并在必要时做出回应。 | M4: 【xx】同学已能意识到从题目中提取关键信息对于算法的重要性，并尝试使用基础的小技巧来缩减常数或降低复杂度。 | N4: 【xx】通过今天的学习，能够在简单的题目中抓住关键性质，并且在部分代码中使用技巧来提升代码效率，成功写出了压轴题的部分分代码，还是不错的。但是在一道用二分优化的题目中，孩子没想到优化方法，后续需要通过不断练习来提高算法优化技巧的熟练度。 | O4: 后续会通过不断练习来提高算法优化技巧的熟练度。
N8: 【xx】通过今天的学习，能够在简单的题目中抓住关键性质，并且在部分代码中使用技巧来提升代码效率。但是在比较复杂的题目中往往难以准确判断切入点，只能做出部分优化，导致最终时间复杂度仍然较高。
A9: 1 | B9: 何奇阳 | C9: A | D9: A | E9: A | F9: A+ | G9: 某CSP-S真题里的折半搜索(双向广搜,小时候玩迷宫题就用过，但是第一次用在图论里)以及某道情况非常丰富的博弈论题。了解了如何正确的处理博弈论的决策，即考虑多种角度和情况分类讨论 下午小考试的题目，T2复习了圆锥曲线和二次方程(误)。 T5，图论的妙用这一块,不过无法否认序列跳跃产生了同构于图的topo结构，自然可以把它转为图论解决，可视作嵌入的逆元吧 T6还告诉了我模拟的妙用，实在太妙用了 | H9: T4一眼觉得区间查询可以上线段树花了一个半小时搓出可持久化……然后，TLE了！直接去世,T5,6已经没空做了 | I9: ***的哈希！这是真欠缺……还是要舍弃"滑板火箭"的数据结构思维，"遇事不决先种树"，数据结构只是工具，无法真正解决根本性问题。 | J9: 今天主要选讲了提高组的真题，聚焦在如何从题目中捕捉特殊性质与关键特点，并结合一些“小技巧”来将原本 O(n²) 或更高复杂度的算法调优到 O(n log n) 或 O(n) 级别。奇阳能够在老师或同学发起讨论时给予回应，课堂上既认真倾听也适时参与。在代码方面，奇阳表现优异，能够迅速捕捉真题中的关键信息，并灵活运用小技巧将原本较慢的解法优化至更高效的算法，思路清晰。在测试中，奇阳通过今天的学习，能够迅速的从题目中抓住关键性质，能够快速的完成前三题，但是在第四题中花费了大量时间，有些时候在做题时太依赖高级的数据结构，需要从题目中多挖掘些性质在考试思考，同时需要注意题目中的部分分，继续加油。 | N9: 【xx】通过今天的学习，能够在简单的题目中抓住关键性质，并且在部分代码中使用技巧来提升代码效率。但是在比较复杂的题目中往往难以准确判断切入点，只能做出部分优化，导致最终时间复杂度仍然较高。
A10: 2 | B10: 祁靖轩 | C10: A+ | D10: A+ | E10: A | F10: A+ | G10: 今天上午主要练习了csp-s2的真题,下午也进行了比赛.做题的收获并非是如何写题目的代码,而是解题的技巧.如假期计划一题需要使用折半搜索以降低代码时间复杂度,跳题中原本看起来是一道非图论的题目,但是如果转变为图上的题目,就知道原来是一个最短(长)路算法思想题.所以,有时候,换个角度看同一个问题,会有不一样的发现. | H10: 测试时的难题没能做出来,没有发现题中的关键点而只是一味地跟着题面走,把难题看的太简单了. | I10: dp数组的状态设计,哈希的应用 | J10: 今天主要选讲了提高组的真题，聚焦在如何从题目中捕捉特殊性质与关键特点，并结合一些“小技巧”来将原本 O(n²) 或更高复杂度的算法调优到 O(n log n) 或 O(n) 级别。靖轩积极参与课堂互动，对于一些常见的算法优化能够很快的反应出来。在代码方面，靖轩表现优异，能够迅速捕捉真题中的关键信息，并灵活运用小技巧将原本较慢的解法优化至更高效的算法，思路清晰。在测试中，靖轩通过今天的学习，能够迅速的从题目中抓住关键性质，能够快速的完成前三题，但是在第四题中花费了大量时间，导致后面的题目没有时间去看，从而没有获取对应的部分分，这块下次可以注意下，需要合理的分配时间，继续加油。
A11: 3 | B11: 陈一实 | C11: A | D11: A | E11: A | F11: A | G11: 第一·二题考的是我们的观察能力（第二题还考了一些基础知识） 假期计划：折半搜索 策略游戏：遇到情况少的博弈，可以进行分类讨论 总结一下：今天学习了一些编程思路，不仅巩固了从前松懈的知识，对于难题的理解也加深了， 这，就是惊天的主题！！！ | H11: 一 道 题 想 了 一 天 ，想 不 到 正 解 | I11: .不用. | J11: 今天主要选讲了提高组的真题，聚焦在如何从题目中捕捉特殊性质与关键特点，并结合一些“小技巧”来将原本 O(n²) 或更高复杂度的算法调优到 O(n log n) 或 O(n) 级别。一实能够在老师或同学发起讨论时给予回应，课堂上既认真倾听也适时参与。在代码方面，一实表现优异，能够迅速捕捉真题中的关键信息，并灵活运用小技巧将原本较慢的解法优化至更高效的算法，思路清晰。在测试中，一实能够迅速的从题目中抓住关键性质，获取了两道题的首 A，其中还有道难度很大的题。总体来说，一实今天表现的很好，几乎能把自己能拿的分都拿了，继续保持。
A12: 4 | B12: 余廷锴 | C12: A | D12: A | E12: A- | F12: A | G12: 在“假期计划”中学习了折半搜索，可以更方便地查询路径，在“策略游戏”中学习了分类讨论的做题方法，使用了少量的博弈；下午进行了复赛模拟，练习了有关hash优化的题目。收获了在做题中要透过现象看本质的道理，如“跳题”本质上是图论题，涉及了许多从一个地方跳到另一个地方的操作，可通过迪杰斯特拉这一最短路径算法解决。 | H12: 在“跳题”中没有想到这是一道图论题；忘记了部分有关抛物线的知识；部分题目没有发现模拟的做法。 | I12: 关于哈希的知识需要更多练习，关于数学的知识有部分遗忘，需要练习（写暑假作业），要练习读题能力。 | J12: 今天主要选讲了提高组的真题，聚焦在如何从题目中捕捉特殊性质与关键特点，并结合一些“小技巧”来将原本 O(n²) 或更高复杂度的算法调优到 O(n log n) 或 O(n) 级别。廷锴积极参与课堂互动，对于一些常见的算法优化能够很快的反应出来。在代码方面，廷锴表现优异，能够迅速捕捉真题中的关键信息，并灵活运用小技巧将原本较慢的解法优化至更高效的算法，思路清晰。在测试中，廷锴能够迅速的从题目中抓住关键性质，做出了两道题难度较大的题。不过在剩下的题目中，廷锴没有获取部分分，希望在后续的考试中，廷锴可以更好的分配考试时间，获取更多的分数，继续加油。
A13: 5 | B13: 郭维皓 | C13: A- | D13: A- | E13: A- | F13: A | G13: 通过折半搜索思想减少所需枚举点数量，运用分类讨论研究简单博弈，容斥原理，问题类型转换,以数据范围倒推最大支持复杂度等 | H13: dfs写炸了，注意力不够惊人，T3错误的维护了单个时间点上的温度而不是温度区间，没有给后续转移留下空间 | I13: 提升注意力 | J13: 今天主要选讲了提高组的真题，聚焦在如何从题目中捕捉特殊性质与关键特点，并结合一些“小技巧”来将原本 O(n²) 或更高复杂度的算法调优到 O(n log n) 或 O(n) 级别。维皓能够在老师或同学发起讨论时给予回应，课堂上既认真倾听也适时参与。在代码方面，维皓基础扎实，对题目特殊性质和优化思路有较好把握，能够在指导下想出核心步骤，但在整体思路与细节实现上还需进一步锻炼。在测试中，维皓能够迅速的从题目中抓住关键性质，然后灵活运用技巧将代码的时间复杂度优化到一个可以完全通过题目的程度，成功使用二分做出了一道较难的题目。在剩下的时间内，维皓也能把所有题目的暴力分实现一遍，还是不错的，继续加油。
A14: 6 | B14: 练皓文 | C14: A- | D14: A- | E14: A- | F14: A- | G14: 早上讲了假期计划和策略游戏两道题目，学到了折半搜索和分类讨论；下午进行了复赛的模拟练习，学到了许多复赛实用知识，如将不显然的图论题目经过分析变成图论题（一个点可以往前或往后跳，由此联想到图论，建立类似边的联系）、将函数图像联立方程（有几个解代表有几个交点）等。 收获：让我认识到了许多题目的本质考点与表面是有不同点的，也让我学会了通过数据大小反推出代码做多能开到多少的时间复杂度。 | H14: 对于题目的理解能力不够，很难看清题目的本质，只能通过特殊测试点或样例分析题意，所以总是与题意有出入，导致题目无法通过或只能通过部分特殊测试点。 | I14: 要多练习复赛题目，提升对题目的理解能力，锻炼思维能力，提升观察力和注意力。 | J14: 今天主要选讲了提高组的真题，聚焦在如何从题目中捕捉特殊性质与关键特点，并结合一些“小技巧”来将原本 O(n²) 或更高复杂度的算法调优到 O(n log n) 或 O(n) 级别。皓文能够在老师或同学发起讨论时给予回应，课堂上既认真倾听也适时参与。在代码方面，皓文基础扎实，对题目特殊性质和优化思路有较好把握，能够在指导下想出核心步骤，但在整体思路与细节实现上还需进一步锻炼。在测试中，皓文能够迅速的从题目中抓住关键性质，然后灵活运用技巧将代码的时间复杂度优化到一个可以完全通过题目的程度，成功优化代码通过了一道题目。但是在一道用二分优化 解“一元二次方程”的题目中，孩子没想到优化方法，非常可惜，后续需要通过不断练习来提高算法优化技巧的熟练度。后续会通过反思加上总结的方法来锻炼建模能力。
A15: 7 | B15: 吴奕淳 | C15: A- | D15: A- | E15: A- | F15: A- | G15: 今天学习了折半搜索（BFS广搜时，可以从一头一尾开始搜索，等两边搜索到同一个点的时候，就可以连成一条路线了）以及策略游戏（在遇到博弈情况的策略游戏时，可以先进行分类讨论，然后对其进行总结），以后要将一些想不到什么算法的与其他算法多进行练习，同时可以通过数据范围倒推出正解的时间复杂度。 | H15: 在复赛模拟赛的题目“最佳拍照地点”中，由于对抛物线不熟悉，导致没有写出来；在题目“射箭”中，对题目分析不够，只写出了暴力写法，没有通过特殊样例点倒推出思路和获得一定分数，更没有写出正解。 | I15: 多学习数学相关问题，防止遇到数学类问题时想不出来。多挖掘题目深层含义，增加题目理解能力。 | J15: 今天主要选讲了提高组的真题，聚焦在如何从题目中捕捉特殊性质与关键特点，并结合一些“小技巧”来将原本 O(n²) 或更高复杂度的算法调优到 O(n log n) 或 O(n) 级别。奕淳能够在老师或同学发起讨论时给予回应，课堂上既认真倾听也适时参与。在代码方面，奕淳基础扎实，对题目特殊性质和优化思路有较好把握，能够在指导下想出核心步骤，但在整体思路与细节实现上还需进一步锻炼。在测试中，奕淳能够迅速的从题目中抓住关键性质，然后灵活运用技巧将代码的时间复杂度优化到一个可以完全通过题目的程度，成功实现出了一道较难的题目，也能很好的观察题目性质，非常好。但是在一道用二分优化 解“一元二次方程”的题目中，孩子没想到优化方法，非常可惜，后续需要通过不断练习来提高算法优化技巧的熟练度。后续会通过反思加上总结的方法来锻炼建模能力。
A16: 8 | B16: 张允泽 | C16: A- | D16: A- | E16: A- | F16: A- | G16: 今天练习了复赛的题目，学习了双端广搜（折半搜索）（假期计划：从起点、终点同时搜索减少时间），简单博弈类型题目拆分成子问题，对子问题进行求解后再求出正确答案（题目策略游戏：将二维矩阵上的问题拆分成一维上的区间问题），可以将一些题目转化为图上的解题。学会了通过观察特殊性质以获取部分分数或者从中找出正解解法等（射箭：测试点1,2只会有两个值，统计值的数量加以判断即可得分），加强了对于题目内涵，解法等内容的剖析。 | H16: 在测试时第二题有关二次函数的题目，已经推导出了有关于根的判别式的内容，距离正解只差一步之遥时放弃该题去做其他题目，并没有继续深入探讨解法，后续再回到该题时思路断了没有解决问题。 | I16: 多加练习复赛题目，培养对于题干的剖析，观察能力（观察到题目需要的解法/简化操作等），学会从题目数据范围/特殊数据发现题目的性质或者解题方法（获取一部分的分数或者从中找出正解），更快，更准确的求解题目。 | J16: 今天主要选讲了提高组的真题，聚焦在如何从题目中捕捉特殊性质与关键特点，并结合一些“小技巧”来将原本 O(n²) 或更高复杂度的算法调优到 O(n log n) 或 O(n) 级别。允泽能够在老师或同学发起讨论时给予回应，课堂上既认真倾听也适时参与。在代码方面，允泽基础扎实，对题目特殊性质和优化思路有较好把握，能够在指导下想出核心步骤，但在整体思路与细节实现上还需进一步锻炼。在测试中，允泽能够迅速的从题目中抓住关键性质，然后灵活运用技巧将代码的时间复杂度优化到一个可以完全通过题目的程度，成功优化代码通过了一道题目。但是在一道用二分优化的题目中，孩子想到优化方法，但是在实现的过程中遇到了问题，需要注意二分要在一个有序数组中进行，继续加油。
A17: 9 | B17: 张岳琳 | C17: A- | D17: A- | E17: A- | F17: A- | G17: 今天学到博弈问题如果比较少可以先分类讨论再总结、可经分析后把非图论问题变成图上问题（如果有的题明确的某个点可到另一个点）、方案数量问题的新思路：合法方案=总方案-不合法方案、看数据范围（根据范围反推算法时间复杂度）、样例性质（合理骗分依据）、根据子任务的特殊性质反推正解思路（策略游戏） | H17: 第2题求根公式记错导致写不出来；第3题数组开小导致样例没过；最后一题没结合样例审题导致思路堵塞 | I17: 多练习动态规划、方案问题，下次做题“骗分”前看一眼数据范围依特殊性质做题 | J17: 今天主要选讲了提高组的真题，聚焦在如何从题目中捕捉特殊性质与关键特点，并结合一些“小技巧”来将原本 O(n²) 或更高复杂度的算法调优到 O(n log n) 或 O(n) 级别。岳琳能够在老师或同学发起讨论时给予回应，课堂上既认真倾听也适时参与。在代码方面，岳琳基础扎实，对题目特殊性质和优化思路有较好把握，能够在指导下想出核心步骤，但在整体思路与细节实现上还需进一步锻炼。在测试中，岳琳能够迅速的从题目中抓住关键性质，然后灵活运用技巧将代码的时间复杂度优化到一个可以完全通过题目的程度，成功优化代码通过了一道题目。但是在一道用二分优化“一元二次方程”的题目中，岳琳想到了解法程的暴力代码，但是没想到优化方法，在后续给孩子讲解后，想到了正确做法，后续需要通过不断练习来提高算法优化技巧的熟练度，继续加油。
A18: 10 | B18: 张梓涵 | C18: A- | D18: B+ | E18: B+ | F18: A- | G18: 在今天上午我们主要是写题，写了之前csp-s的真题,如2022年真题假期计划、策略游戏，学习了折半搜索，就是可以从问题的中间开始思考，把一整个问题分成两个子问题，同时也初步接触了博弈论，同时也在灵活利用图论知识，将Dijkstra的思想运用到类似非图论题目上，多想一些解题方法，学会多方位思考问题，有时可以看这道题目的背后的真正目的，有时也可以从答案出发，将总方案-非法方案得出合法方案 | H18: 在下午测试时依旧太过沉迷于做出前两道题目，而导致在写后面题目的部分分时没时间，部分分依旧没拿全，同时也对一些题目想的太过复杂，应适当发散一下思维，避免太死磕在一种思路上，多想一些解题方法，学会多方位思考问题，有时可以看这道题目的背后的真正目的，有时也可以从答案出发，将总方案-非法方案得出合法方案，我就没想到。 | I18: 对于类似于数学类的题目上应进行更深入的思考，将一道题目进行更彻底的思考，对题目的本质进行更加深刻的分析，在写有关数学类的题时可以灵活运用学过的数据结构 | J18: 今天主要选讲了提高组的真题，聚焦在如何从题目中捕捉特殊性质与关键特点，并结合一些“小技巧”来将原本 O(n²) 或更高复杂度的算法调优到 O(n log n) 或 O(n) 级别。梓涵积极参与课堂互动，对于一些常见的算法优化能够很快的反应出来。在代码方面，梓涵基础扎实，对题目特殊性质和优化思路有较好把握，能够在指导下想出核心步骤，但在整体思路与细节实现上还需进一步锻炼。在测试中，梓涵通过今天的学习，能够在简单的题目中抓住关键性质，能够想到题目的暴力解法，但是在没有成功的把题目优化，非常可惜，在做题的时候需要多想一想题目是否和之前学过的某个算法类似，通过之前学过的算法来优化时间复杂度，继续加油。
A19: 11 | B19: 刘孟霖 | C19: A- | D19: B+ | E19: B+ | F19: B+ | G19: 学会看数据范围，数据范围可能在提醒你一些事情，比如 2025-xp0-03-T1 中的数据范围就已经在提醒这道题要注意数据的奇偶性； 对于某些题目，运用数学方法可以加快程序运行速度，比如 2025-xp05-03-T2 中可以利用Δ(根的判别式)来判断函数图像之间是否有交点； 在做题时可以联想一下，比如 2025-xp05-03-T5 中可以把题干中的“跳题”和从当前题目往前做的做法和图论知识点联系在一起，用图论可以让题目更简单(打破出题者给你的假象,拆穿出题者的谎言)； 当做难题时不一定要往高级的算法上去想，比如 2025-xp05-03-T6 中看起来很难解，但如果转换一下思路，看透某些联系，做题就变简单了(这一道题是测试最难的题，但用的是模拟算法)； 做题时可以针对数据特性分类讨论，逐渐推出正解。 | H19: 在做“擦黑板”时没有注意到数据范围中的数据特性，导致没有完全通过；在做“最佳拍照地点”时忘记了根的判别式是什么导致没有通过；在做“跳题”时没有看透题目的本质是道图论题目导致没有完全通过；在做“修复二进制串”的时候因为没有合理分配时间导致时间不足只写了个暴力导致没有完全通过； | I19: 后续计划：复习线段树的写法，加深手搓线段树代码的熟练度(在做题的时候想用线段树但是忘了怎么写了)；多默写几次ST表的模板，并加深对该模板的印象；多做一些利用数学知识减少代码复杂度的题目，增加刷题经验。 | J19: 今天主要选讲了提高组的真题，聚焦在如何从题目中捕捉特殊性质与关键特点，并结合一些“小技巧”来将原本 O(n²) 或更高复杂度的算法调优到 O(n log n) 或 O(n) 级别。孟霖能够在老师或同学发起讨论时给予回应，课堂上既认真倾听也适时参与。在代码方面，孟霖基础扎实，对题目特殊性质和优化思路有较好把握，能够在指导下想出核心步骤，但在整体思路与细节实现上还需进一步锻炼。在测试中，孟霖能够在简单的题目中抓住关键性质，并且在部分代码中使用技巧来提升代码效率，成功写出了压轴题的部分分代码，还是不错的。但是在一道用二分优化的题目中，孩子没想到优化方法，后续需要通过不断练习来提高算法优化技巧的熟练度，继续加油。
A20: 12 | B20: 张世昌 | C20: A- | D20: B+ | E20: B+ | F20: B+ | G20: 我们今天学习了几道比较难的题，一是假期计划，这道题需要用到Meet In The Middle，也就是折半搜索，我们把本来搜一遍东西拆成两半去搜，需要用到迪杰斯特拉最短路算法；第二道题是策略游戏，我学到了在遇到这种情况比较小的博弈时，可以进行分类讨论，然后进行总结；第三道题是最佳拍摄地点，这道题就是考验大家数学怎么样，把数学和代码结合，通过联立方程查看是否有解；跳题这道题更有趣，我们需要跟具题里面一些和图毫不相关的意思，推理出要把这道题转化成一个图上的题目，进行迪杰斯特拉最短路计算。 | H20: 在下午写题时对着第一题想了将近两个小时，导致后面连暴力的时间都不太够了，有些题没挖掘到隐含信息。 | I20: 对于一些要转换成其他方法去解的题目要多加练习，以后要多观察题目，找到题目里的隐含信息； | J20: 今天主要选讲了提高组的真题，聚焦在如何从题目中捕捉特殊性质与关键特点，并结合一些“小技巧”来将原本 O(n²) 或更高复杂度的算法调优到 O(n log n) 或 O(n) 级别。世昌能够在老师或同学发起讨论时给予回应，课堂上既认真倾听也适时参与。在代码方面，世昌基础扎实，对题目特殊性质和优化思路有较好把握，能够在指导下想出核心步骤，但在整体思路与细节实现上还需进一步锻炼。在测试中，世昌能够在简单的题目中抓住关键性质，并且在部分代码中使用技巧来提升代码效率，成功写出了一道难题的部分分代码，还是不错的。但是在一道用二分优化的题目中，孩子没想到优化方法，后续需要通过不断练习来提高算法优化技巧的熟练度，继续加油。
A21: 13 | B21: 熊子轩 | C21: A- | D21: B | E21: B | F21: B | G21: 在题目假期计划，学习了折半搜索的思想，通过确定其余点再结合确定之间的点来优化算法 题目策略游戏：博弈题目中若博弈情况比较小可以通过分类讨论 跳题：一些看起来并不是图论的题目可能通过分析后与图论题目做法相识从而转换成图论题目做 | H21: 在测试时的T2中耗费了过多时间，时间分配不合理，导致后面一些题目部分分代码没有写完，考试时候心态不够好容易红温 | I21: 要多加练习思维类的题目，练习分析题目能力 | J21: 今天主要选讲了提高组的真题，聚焦在如何从题目中捕捉特殊性质与关键特点，并结合一些“小技巧”来将原本 O(n²) 或更高复杂度的算法调优到 O(n log n) 或 O(n) 级别。子轩能够在老师或同学发起讨论时给予回应，课堂上既认真倾听也适时参与。在代码方面，子轩基础扎实，对题目特殊性质和优化思路有较好把握，能够在指导下想出核心步骤，但在整体思路与细节实现上还需进一步锻炼。在测试中，子轩能够在简单的题目中抓住关键性质，并且在部分代码中使用技巧来提升代码效率，成功写出了一道难题的部分分代码，还是不错的。但是在一道用二分优化的题目中，孩子没想到优化方法，后续需要通过不断练习来提高算法优化技巧的熟练度，继续加油。
... A24: 16 | B24: 金智宸 | C24: A- | D24: B | E24: B | F24: B- | G24: 折半搜索；遇到情况较少的博弈类题目，先分类讨论，在总结；数学中判断两个函数是否有交点，联立方程通过德尔塔(小三角 = b^2+4ac)看是否有解；把一些不是图论的题目经过(神秘)分析转换后变成图上的题目；在求符合某种特殊的方案数时，如果直接计算能不太行，就可以用：合法方案数 = 总数-不合法数，用于解决一些求方案数(计数)问题。把之前没有学好的东西，巩固的更好，对于难题就有更多的手段去解决。 | H24: 没有把控好时间，只顾着做一道题；没有仔细的观察题目导致扣分，数组开小导致越界。 | I24: 如何把一些不是图论的题目经过(神秘)分析转换后变成图上的题目的(神秘)方法；博弈类题目的分类讨论；折半搜索；练习dp的题目来多加练习设计状态（转移方程）的能力 | J24: 今天主要选讲了提高组的真题，聚焦在如何从题目中捕捉特殊性质与关键特点，并结合一些“小技巧”来将原本 O(n²) 或更高复杂度的算法调优到 O(n log n) 或 O(n) 级别。智宸在课堂上能够专心听讲并在必要时做出回应。在代码方面，智宸已能意识到从题目中提取关键信息对于算法的重要性，并尝试使用基础的小技巧来缩减常数或降低复杂度。在测试中，智宸能够在题目中抓住关键性质，成功写出了一些题目的部分分代码，还是不错的。但是在一道用二分优化的题目中，孩子没想到优化方法，后续需要通过不断练习来提高算法优化技巧的熟练度。后续会通过不断练习来提高算法优化技巧的熟练度。
N27: 【xx】能够迅速的从题目中抓住关键性质，然后灵活运用技巧将代码的时间复杂度优化到一个可以完全通过题目的程度，成功使用二分做出了一道较难的题目。不过在做一道哈希问题时，【xx】对于哈希有些忘记了，在老师讲解后，会想起哈希的原理及作用，后续可以再去练习下哈希。
N28: 【xx】能够迅速的从题目中抓住关键性质，然后灵活运用技巧将代码的时间复杂度优化到一个可以完全通过题目的程度，成功优化代码通过了一道题目。但是在一道用二分优化的题目中，孩子没想到优化方法，后续需要通过不断练习来提高算法优化技巧的熟练度。
N29: 【xx】通过今天的学习，能够在题目中抓住关键性质，并且在部分代码中使用技巧来提升代码效率，成功写出了压轴题的部分分代码，还是不错的。但是在一道用二分优化的题目中，孩子没想到优化方法，后续需要通过不断练习来提高算法优化技巧的熟练度。
A31: 代码能力(当天最难的知识点 或 所有基础都理解就是A 或 班级表现前70%) A / B 理解能力(当天最难的知识点 或 所有基础都理解就是A 或 班级表现前70%) A / B 摸底测或代码模板默写(统称为小检测，4-5-1 对应A-B-C) A:30 B:20 C:10 最终表现 A类 >= 80分 B类 >= 60分 C类 < 60分
A38: 代码能力取决于总分数
A39: 理解能力取决于考试第二题是否 ac

Sheet Day3反馈表
A1: 暑假集训学习反馈卡 | N1: 张陈曦暑假集训学习反馈卡
B4: 姓名 | D4: 金智宸
P5: 测试内容: CSP2022初赛真题
B6: 课堂积极性 | D6: 理解能力 | F6: 代码能力 | H6: 综合评价 | P6: 基础选择得分 (满分30) | R6: 程序阅读得分 (满分40) | U6: 完善代码得分 (满分30) | W6: 总分 (浙江晋级线78.5)
B8: =VLOOKUP(D4,day3!$B$7:$G$100,2,FALSE) -> A- | D8: =VLOOKUP(D4,day3!$B$7:$G$100,3,FALSE) -> B | F8: =VLOOKUP(D4,day3!$B$7:$G$100,4,FALSE) -> B | H8: =VLOOKUP(D4,day3!$B$7:$G$100,5,FALSE) -> B- | P8: 30 | R8: 28.5 | U8: 30 | W8: =SUM(P8:V10) -> 88.5
B12: 学生总结 | C12: 收获 (今天学到了/回忆起了什么知识) | E12: =VLOOKUP(D4,day3!$B$7:$G$100,6,FALSE) -> 折半搜索；遇到情况较少的博弈类题目，先分类讨论，在总结；数学中判断两个函数是否有交点，联立方程通过德尔塔(小三角 = b^2+4ac)看是否有解；把一些不是图论的题目经过(神秘)分析转换后变成图上的题目；在求符合某种特殊的方案数时，如果直接计算能不太行，就可以用：合法方案数 = 总数-不合法数，用于解决一些求方案数(计数)问题。把之前没有学好的东西，巩固的更好，对于难题就有更多的手段去解决。 | P12: 学生总结 | Q12: 收获 (今天学到了/回忆起了什么知识) | T12: 二分查找、哈夫曼编码
C14: 学生自我反思 (在测试/学习中出现了什么失误/错误) | E14: =VLOOKUP(D4,day3!$B$7:$Z$100,7,FALSE) -> 没有把控好时间，只顾着做一道题；没有仔细的观察题目导致扣分，数组开小导致越界。 | Q14: 学生自我反思 (在测试/学习中出现了什么失误/错误) | T14: 阅读程序： （2）、1（不会）、2（我赌它两行输出相同）、5（因为第一题赌它俩函数输出相同，所以直接拿dp表算的，然后就错了） （3）、3（没算对）、4（没算对）
C16: 计划 (在什么知识点上还需要更多练习/讲解) | E16: =VLOOKUP(D4,day3!$B$7:$Z$100,8,FALSE) -> 如何把一些不是图论的题目经过(神秘)分析转换后变成图上的题目的(神秘)方法；博弈类题目的分类讨论；折半搜索；练习dp的题目来多加练习设计状态（转移方程）的能力 | Q16: 计划 (在什么知识点上还需要更多练习/讲解) | T16: 树、图、动态规划
B18: 教师寄语 | C18: =VLOOKUP(D4,day3!$B$7:$Z$100,9,FALSE) -> 今天主要选讲了提高组的真题，聚焦在如何从题目中捕捉特殊性质与关键特点，并结合一些“小技巧”来将原本 O(n²) 或更高复杂度的算法调优到 O(n log n) 或 O(n) 级别。智宸在课堂上能够专心听讲并在必要时做出回应。在代码方面，智宸已能意识到从题目中提取关键信息对于算法的重要性，并尝试使用基础的小技巧来缩减常数或降低复杂度。在测试中，智宸能够在题目中抓住关键性质，成功写出了一些题目的部分分代码，还是不错的。但是在一道用二分优化的题目中，孩子没想到优化方法，后续需要通过不断练习来提高算法优化技巧的熟练度。后续会通过不断练习来提高算法优化技巧的熟练度。 | P18: 教师寄语 | Q18: 今天的课程内容是一次初赛模拟赛和讲解，以及2022年真题的测试与讲解。今天陈曦的表现很不错，超过了浙江晋级分数线整整10分，在基础选择和完善代码部分都是满分，这个成绩已经非常不错了。明天我们会把所有J组的知识点再过一遍，做最后一遍查漏补缺，最后做一下2023的真题卷，作为我们集训营内容的收尾，希望陈曦可以在明天也可以获得一个好成绩。
A42: 王成峰寒假集训学习反馈卡
C46: 今日知识点 | E46: =$G$4 -> 0
C47: 课堂积极性 | E47: 代码完成速度 | G47: 每日测试成绩 | I47: 综合评价
C49: A | E49: A | G49: A+ | I49: A
C53: 学生总结 | D53: 收获 (今天学到了/回忆起了什么知识) | F53: 今天增强巩固了二分答案，增强了对二分答案的应用，进行了模拟来解决问题，比如区间二分答案的模拟。 还有一些二分答案的小技巧，比如在模拟二分答案时，要认真审题，理解题目想让我们做的事是什么，然后可以对于一些复杂的代码进行一些简化和优化，这样反而可以增强代码的准确性。
D55: 反思 (在测试/学习中出现了什么失误/错误) | F55: 在考试时，对于解题过程复杂繁琐的题，解题过程的分析还需更加仔细，不然会发生一些不仔细的小错误。
C57: 教师寄语 | D57: 今天是成峰在二分算法的最后一课，今天的题目会更加地综合，更考验成峰的代码实现能力。现在二分算法的问题思想成峰已经理解地非常深刻了，能够在对应的问题中使用这个算法。代码实现的基本功还是有待提高，在实现时，会在一些地方会出些小错误。在寒假后的春季课程中，建议加强中等难度的模拟类问题的训练，可以获得更好的效果。

Sheet day4
A1: 课程内容 | B1: 姓名 | C1: 课堂积极性 | D1: 代码能力（考试情况） | E1: 理解能力 | F1: 综合评价 | G1: 总结 | H1: 反思 | I1: 计划 | J1: 反馈结果 | K1: 总评 | L1: 课堂积极性 | M1: 代码能力（考试情况） | N1: 理解能力 | O1: 后续建议
A2: 今天选讲了提高组的真题，重点讲解了在面对冗长代码时如何通过模块化拆分、封装函数来保持逻辑清晰，并介绍了哈希这一高效优化技巧，帮助同学们在解决字符串及模拟问题时更加得心应手。 | B2: 葛义 | C2: B- | D2: C+ | E2: C+ | F2: C+ | J2: =A$2&""&SUBSTITUTE(IF(OR(C2="A",C2="A-",C2="A+"),L$2,IF(OR(C2="B",C2="B-",C2="B+"),L$3,L$4)),"【xx】",B2)&""&SUBSTITUTE(IF(OR(D2="A",D2="A-",D2="A+"),N$2,IF(OR(D2="B",D2="B-",D2="B+"),N$3,N$4)),"【xx】",B2)&""&SUBSTITUTE(IF(OR(E2="A",E2="A-",E2="A+"),M$2,IF(OR(E2="B",E2="B-",E2="B+"),M$3,M$4)),"【xx】",B2)&""&SUBSTITUTE(IF(OR(F2="A",F2="A-",F2="A+"),O$2,IF(OR(F2="B",F2="B-",F2="B+"),O$3,O$4)),"【xx】",B2) -> 今天选讲了提高组的真题，重点讲解了在面对冗长代码时如何通过模块化拆分、封装函数来保持逻辑清晰，并介绍了哈希这一高效优化技巧，帮助同学们在解决字符串及模拟问题时更加得心应手。葛义同学课堂积极度良好。能够参与互动，跟上课堂节奏，表现出学习热情。葛义在本次测试中表现不错，葛义能够解决基础的问题，在做其他题目时能够去获取部分分数，在面对中等题的时候，也能能够分析出问题的类型，但是孩子对于普及组二分 or 双指针的使用不是很熟练，实现代码的时候遇到了困难，需要加强基础算法的熟练度，继续加油。后续会通过不断练习来提高算法优化技巧的熟练度。 | K2: =IF(D2="A",1,0)*30+IF(D2="B",1,0)*20+IF(D2="C",1,0)*10+IF(E2="A",1,0)*30+IF(E2="B",1,0)*20+IF(E2="C",1,0)*10+IF(F2="A",1,0)*30+IF(F2="B",1,0)*20+IF(F2="C",1,0)*10 -> 0 | L2: 【xx】同学课堂积极度高。能主动参与讨论，积极回答问题，带动了课堂氛围。 | M2: 【xx】在本次测试中表现非常出色，考了班里前三名，【xx】能够迅速的解决基础的问题，在面对中等题的时候，也能能够很好的分析出问题的类型，非常迅速的使用对应的算法解决问题。在面对一些困难题时，孩子能够拿到一定的部分分。不过在分析正解时还是缺少点经验，比如说在做 dp 问题时，还是较难分析出题目的dp属性，后续需要加强对于难题的练习，继续加油。 | N2: 【xx】同学对于模块化拆分、函数封装及哈希优化的原理理解深入，能够在思考问题时迅速抓住核心，利用到今天所学到的知识点，【xx】在写代码时能够通过封装函数将冗长的代码拆解成多个模块，然后独立调用，使得代码读起来简洁。并且能够巧妙的通过哈希来解决查找问题。
L3: 【xx】同学课堂积极度良好。能够参与互动，跟上课堂节奏，表现出学习热情。 | M3: 【xx】在本次测试中表现不错，【xx】能够迅速的解决基础的问题，在面对中等题的时候，也能能够分析出问题的类型，能够使用对应的算法解决问题，但是实现代码的速度还是有些慢，还是需要加强基础算法的熟练度。在面对一些困难题时，孩子能够拿到一定的部分分。不过在分析正解时还是缺少点经验，比如说在做 dp 问题时，还是较难分析出题目的dp属性，后续需要加强对于难题的练习，继续加油。 | N3: 【xx】同学对核心思路掌握较好，能够在部分题目中运用模块化和哈希技巧。【xx】在写代码时能够通过封装函数将冗长的代码拆解成多个模块，然后独立调用，使得代码读起来简洁。 | O3: 后续会通过反思加上总结的方法来锻炼优化建模能力。
L4: 【xx】同学能认真听讲，但互动较少。后续会加强与孩子的互动，让孩子在较轻松的氛围中练习发言，逐步提升参与热情。 | M4: 【xx】在本次测试中表现不错，【xx】能够解决基础的问题，在做其他题目时能够去获取部分分数，在面对中等题的时候，也能能够分析出问题的类型，但是孩子对于普及组二分 or 双指针的使用不是很熟练，实现代码的时候遇到了困难，需要加强基础算法的熟练度，继续加油。 | O4: 后续会通过不断练习来提高算法优化技巧的熟练度。
B9: 吴奕淳 | C9: A | D9: A | E9: A | F9: A+ | G9: 今天在课上学习了异或前缀和(相当于普通前缀和的改版，每一位数字都与前一位相异或，当要查询[l~r]这个区间时，设使用a数组保存异或的结果，只需返回a[r]^a[l-1]即可)还学习了异或哈希（用于维护出现字数是否为偶数）以及和哈希（维护每个对象是否只出现了一次）。 | H9: 在比赛中想到了思路，但不知道如何快速计算数字在二进制下的最高位，导致只写了暴力代码；同时，在第一、二题中一开始没有开long long，导致浪费了一些时间去找bug。最后，在题目“异异或或异异或”中，写暴力写法时，没有注意到异或和小于号的优先级，导致耗了一段时间去测试哪里出了问题 | I9: 在做题时，多注意题目的数据范围，防止因开错数据类型导致错误。统计，谨记各种符号的优先级，防止因优先级导致错误。多学一些C++自带函数，减少因不知道用什么函数而出现的错误。 | J9: 今天选讲了提高组的真题，重点讲解了在面对冗长代码时如何通过模块化拆分、封装函数来保持逻辑清晰，并介绍了哈希这一高效优化技巧，帮助同学们在解决字符串及模拟问题时更加得心应手。奕淳课堂积极度良好。能够参与互动，跟上课堂节奏，表现出学习热情。奕淳对于模块化拆分、函数封装及哈希优化的原理理解深入，能够在思考问题时迅速抓住核心，利用到今天所学到的知识点，奕淳 在写代码时能够通过封装函数将冗长的代码拆解成多个模块，然后独立调用，使得代码读起来简洁。并且能够巧妙的通过哈希来解决查找问题。奕淳在本次测试中表现非常出色，考了班里前三名，奕淳能够迅速的解决基础的问题，在面对中等题的时候，也能能够很好的分析出问题的类型，非常迅速的使用对应的算法解决问题。在面对一些困难题时，孩子能够拿到一定的部分分。不过在分析正解时还是缺少点经验，比如说在做 dp 问题时，还是较难分析出题目的dp属性，后续需要加强对于难题的练习，继续加油。
B10: 余廷锴 | C10: A+ | D10: A+ | E10: A | F10: A+ | G10: 今天我学到了有关哈希的知识，如射箭比赛中的异或哈希（可以维护元素出现次数是否为偶数次）与星战中的和哈希（可以维护每样东西是否只出现过一次），可以用来优化许多代码（不止可以运用于字符串，还可以与图论等相结合），虽然因为运用了随机数，可能出现错误，但概率可以几乎忽略不计，视为一种正解，学习了位运算中有关按位异或（满足交换律与结合律）的知识，比如前缀异或和，下午进行了复赛模拟，训练了思维能力。了解了csp-s复赛中的一些真题，它们需要一定的数学基础。 | H10: 在复赛模拟中有部分暴力分没有拿全，一些正解的性质没有在比赛中发现。 | I10: 一些有关思维练习的内容还需训练，位运算的一些性质还要多多了解，练习观察题解关键思路的能力。 | J10: 今天选讲了提高组的真题，重点讲解了在面对冗长代码时如何通过模块化拆分、封装函数来保持逻辑清晰，并介绍了哈希这一高效优化技巧，帮助同学们在解决字符串及模拟问题时更加得心应手。廷锴课堂积极度高。能主动参与讨论，积极回答问题，带动了课堂氛围。廷锴对于模块化拆分、函数封装及哈希优化的原理理解深入，能够在思考问题时迅速抓住核心，利用到今天所学到的知识点，廷锴在写代码时能够通过封装函数将冗长的代码拆解成多个模块，然后独立调用，使得代码读起来简洁。并且能够巧妙的通过哈希来解决查找问题。廷锴在本次测试中表现非常出色，考了班里前三名，廷锴能够迅速的解决基础的问题，在面对中等题的时候，也能能够很好的分析出问题的类型，非常迅速的使用对应的算法解决问题。在面对一些困难题时，孩子能够拿到一定的部分分。不过在分析正解时还是缺少点经验，比如说在做 dp 问题时，还是较难分析出题目的dp属性，后续需要加强对于难题的练习，继续加油。
B11: 陈一实 | C11: A | D11: A | E11: A | F11: A | G11: 主要学习了一些有关哈希的内容，和前缀异或和 | H11: 遇到了不知名但是致命的错误 | I11: 有关哈希中随机数int 的内容 | J11: 今天选讲了提高组的真题，重点讲解了在面对冗长代码时如何通过模块化拆分、封装函数来保持逻辑清晰，并介绍了哈希这一高效优化技巧，帮助同学们在解决字符串及模拟问题时更加得心应手。一实课堂积极度高。能主动参与讨论，积极回答问题，带动了课堂氛围。一实对于模块化拆分、函数封装及哈希优化的原理理解深入，能够在思考问题时迅速抓住核心，利用到今天所学到的知识点，一实在写代码时能够通过封装函数将冗长的代码拆解成多个模块，然后独立调用，使得代码读起来简洁。并且能够巧妙的通过哈希来解决查找问题。一实在本次测试中表现非常出色，考了班里前三名，一实能够迅速的解决基础的问题，在面对中等题的时候，也能能够很好的分析出问题的类型，非常迅速的使用对应的算法解决问题。在面对一些困难题时，孩子能够拿到一定的部分分。不过在分析正解时还是缺少点经验，比如说在做 dp 问题时，还是较难分析出题目的dp属性，后续需要加强对于难题的练习，继续加油。
B12: 张允泽 | C12: A | D12: A | E12: A- | F12: A | G12: 今天分析了前几年的几道csp-s真题，如24年的超速检测（由暴力方法联想到记录超速区间贪心，再由超速区间贪心转变到测速仪区间贪心的正解），22年的星战（由分析题目操作推断出与基环树都的相同点，想到维护出度的暴力方法，再依据时间复杂度的瓶颈对症下药，反向站在入度的角度考虑，将遍历点修改出度转变成常数级的维护入度0/最大值的方法，但仍然会出现冲突，便可联想到哈希，给予每一个点随机权值计算贡献的正解）。学习了一些复赛的做题技巧： 1.异或前缀和（T6异异或或异异或）:如加法前缀和的思路一样，O(n)线性维护异或和数组之后用O（1）的复杂度求得区间内的异或和，再通过仔细分析题面得出判断最高位是否是1的正解； 2.随机化哈希： 射箭游戏 、 星战：当数据处理容易出现冲突时，赋予每个点一个随机权值，利用随机数的方式规避冲突风险（并不是100%正确，但错误的概率已经小的可以忽略不计） | H12: 1.测试中T1第三条边，没有开长整型long long ，导致int类型溢出部分测试点WA，各种方法尝试了半个小时才发现是数据类型的问题，耽误了很多时间 2.T2添加零：做题时已经将每一个点的需求值由条件转化出来，到这步为止都与正解相符，但没有观察到数据的特性，选择了一条会超时的路线，最终只取得了50分 | I12: 复习异或前缀和以及随机化思想，抽出空闲时间分析往年真题，摸清做题线路，并学会由暴力作法，题目数据，特性等一步一步分析得出正解，做题时要能通过数据范围/数据特殊性质捕捉到有关解法的思路，再加以分析，尝试最终推测出正确解法。 | J12: 今天选讲了提高组的真题，重点讲解了在面对冗长代码时如何通过模块化拆分、封装函数来保持逻辑清晰，并介绍了哈希这一高效优化技巧，帮助同学们在解决字符串及模拟问题时更加得心应手。允泽课堂积极度良好。能够参与互动，跟上课堂节奏，表现出学习热情。允泽对于模块化拆分、函数封装及哈希优化的原理理解深入，能够在思考问题时迅速抓住核心，利用到今天所学到的知识点，允泽在写代码时能够通过封装函数将冗长的代码拆解成多个模块，然后独立调用，使得代码读起来简洁。并且能够巧妙的通过哈希来解决查找问题。允泽在本次测试中表现不错，允泽能够迅速的解决基础的问题，在面对中等题的时候，也能能够分析出问题的类型，能够使用对应的算法解决问题，但是实现代码的速度还是有些慢，还是需要加强基础算法的熟练度。在面对一些困难题时，孩子能够拿到一定的部分分。不过在分析正解时还是缺少点经验，比如说在做 dp 问题时，还是较难分析出题目的dp属性，后续需要加强对于难题的练习，继续加油。
B13: 郭维皓 | C13: A- | D13: A- | E13: A- | F13: A | G13: string 申必算法哈希[2]={“异或哈希”，“和哈希”};sting &a[]=*申必算法哈希;a[0]=运用异或和为零，该数字的出现次数大概率为偶数的必要条件，用哈希随机大数字将其转化为充分条件（大概率），a[1]=出度总和为N是N个点出度均为1的必要条件， 同样用哈希随机大数字将其转化为充分条件； ！！十年OI一场空，不开____ ____见祖宗 不可以，总司令*T ________________ ________________ | H13: 注意力不够 | I13: 提升注意力 | J13: 今天选讲了提高组的真题，重点讲解了在面对冗长代码时如何通过模块化拆分、封装函数来保持逻辑清晰，并介绍了哈希这一高效优化技巧，帮助同学们在解决字符串及模拟问题时更加得心应手。维皓课堂积极度良好。能够参与互动，跟上课堂节奏，表现出学习热情。维皓对核心思路掌握较好，能够在部分题目中运用模块化和哈希技巧。维皓在写代码时能够通过封装函数将冗长的代码拆解成多个模块，然后独立调用，使得代码读起来简洁。维皓在本次测试中表现不错，维皓能够迅速的解决基础的问题，在面对中等题的时候，也能能够分析出问题的类型，能够使用对应的算法解决问题，但是实现代码的速度还是有些慢，还是需要加强基础算法的熟练度。在面对一些困难题时，孩子能够拿到一定的部分分。不过在分析正解时还是缺少点经验，比如说在做 dp 问题时，还是较难分析出题目的dp属性，后续需要加强对于难题的练习，继续加油。后续会通过反思加上总结的方法来锻炼优化建模能力。
B14: 祁靖轩 | C14: A- | D14: A- | E14: A- | F14: A- | G14: 今天上午继续练习了CSP-S2真题,下午依旧进行测试.一天一天的不断练习能让我们增加对题目的熟练度,增强对知识的理解,从而让我们应对赛时难题时更加游刃有余.今天学到最有价值的知识就是使用哈希并用随机数映射数据以减小时间复杂度,以前没有想过这种解决方法,感觉很新奇 | H14: 测试的时候对于难题花费的时间有点长了,虽然做出了最难题,但如果是真正的比赛,反而不如拿了暴力分后去完成简单题,但对于平常的练习,努力功课难题还是很有意义的. | I14: 哈希->字符串哈希,了解哈希冲突及题目数据会怎样卡哈希及其应对方法,还有使用随机数时利用哈希的思想进行解题. | J14: 今天选讲了提高组的真题，重点讲解了在面对冗长代码时如何通过模块化拆分、封装函数来保持逻辑清晰，并介绍了哈希这一高效优化技巧，帮助同学们在解决字符串及模拟问题时更加得心应手。靖轩课堂积极度良好。能够参与互动，跟上课堂节奏，表现出学习热情。靖轩对核心思路掌握较好，能够在部分题目中运用模块化和哈希技巧。靖轩在写代码时能够通过封装函数将冗长的代码拆解成多个模块，然后独立调用，使得代码读起来简洁。靖轩在本次测试中表现不错，靖轩能够迅速的解决基础的问题，并且靖轩是整个 Xp05 唯一一个做出最后一题的同学，非常厉害，不过由于时间关系，没有时间去实现前面的中等题，是比较可惜的，需要加强对时间的把控，继续加油。
B15: 熊子轩 | C15: A- | D15: A- | E15: A- | F15: A- | G15: 超速检测：通过观察题目特性发现车辆超速的特点从而抽象成区间选点的贪心题目求解 射箭比赛：依旧通过观察题目特性加上分析发现警长只能在偶数时且数字出现次数为偶数次时能获胜，从而得到将数字异或判断是否为0，但是偶数->异或和为0，但和为0不一定偶数，所以使用异或哈希将数值变为大随机数从而大大减少出错可能性（出错概率忽略不计） 星战：还是观察发现题目要求一个时刻图是否为内向の基环数，通过维护当前出边个数与权值乘积与单个数累加是否相等，再通过和哈希将数值变大降低出错概率 | H15: 测试时T6没有考虑到异或与小于号间优先级的问题，导致浪费了约50分钟时间 | I15: 需要提升对思维类题目抽象分析的过程，提升自己的注意力（分析题目性质），做题先打暴力分再看结合样例特殊性质分析 | J15: 今天选讲了提高组的真题，重点讲解了在面对冗长代码时如何通过模块化拆分、封装函数来保持逻辑清晰，并介绍了哈希这一高效优化技巧，帮助同学们在解决字符串及模拟问题时更加得心应手。子轩课堂积极度良好。能够参与互动，跟上课堂节奏，表现出学习热情。子轩对核心思路掌握较好，能够在部分题目中运用模块化和哈希技巧。子轩在写代码时能够通过封装函数将冗长的代码拆解成多个模块，然后独立调用，使得代码读起来简洁。子轩在本次测试中表现不错，子轩能够迅速的解决基础的问题，在面对中等题的时候，也能能够分析出问题的类型，能够使用对应的算法解决问题，但是实现代码的速度还是有些慢，还是需要加强基础算法的熟练度。在面对一些困难题时，孩子能够拿到一定的部分分。同时需要注意当在被一道题目卡的时候，不妨看看其他题目，同时可以通过调试等手段来判断出代码是哪写错了，继续加油。
B16: 何奇阳 | C16: A- | D16: A- | E16: A- | F16: A- | G16: 学了异或前缀和，哈希依赖随机性的妙用（虽然但是会不会用另说），学名”和哈希“和”异或哈希“，分别用于维护奇偶统计和”唯一性“之类的统计等问题，以及某些图论和dp的小思想 T4的dp表明可以考虑对情况的分类来设计状态（对于情况可以分类为较为有限的数量时。可以考虑使用， T5中，需要注意LCA和距离并不是必然联系的，LCA的关键在“祖先“性质，是在有根树中，但T5的树是无根的，故处理T5时候应该正确的想找到两点间路径中点（或者说路径这个子树的重心，这个表述比较形式化和复杂化，但是准确的能够表述T5中这条链中点可以选到两个点的事实），另外积累一下，欧拉环游长度不需要枚举，可以直接由2*(n-1)计算，最后关于舍弃最长链的问题也积累一下，最后注意一下向上下取整的问题，是在一系列问题中值得讨论的，实在不行搓一下分类。 最后T6中的，积累一下二进制中，最高位对其大小有决定性影响，故处理问题时可以考虑针对最高位处理（其实个人感觉T6有点数位dp的意思，但是不知道能不能算） | H16: 不会骗分，没决心骗分，别的方面……有的思路比较玄学吧，能想出来正解都是奇迹。 | I16: dp还得练，二进制位运算的一些性质值得再去研究一下，另外考虑领一领部分分，课程中每道题目都会讲清楚暴力解法就是在告诉我这个，但是我似乎总是下不去某种决心，非要想出正解来……这个得把心态调整好，牢记考试“以大局为重以得分为主”的原则 | J16: 今天选讲了提高组的真题，重点讲解了在面对冗长代码时如何通过模块化拆分、封装函数来保持逻辑清晰，并介绍了哈希这一高效优化技巧，帮助同学们在解决字符串及模拟问题时更加得心应手。奇阳课堂积极度良好。能够参与互动，跟上课堂节奏，表现出学习热情。奇阳对核心思路掌握较好，能够在部分题目中运用模块化和哈希技巧。奇阳在写代码时能够通过封装函数将冗长的代码拆解成多个模块，然后独立调用，使得代码读起来简洁。奇阳在本次测试中表现不错，比赛前期表现非常出色，曾一度到达前二，奇阳能够迅速的解决基础的问题，在面对中等题的时候，也能能够分析出问题的类型，能够使用对应的算法解决问题，但是实现代码的速度还是有些慢，还是需要加强基础算法的熟练度。在面对一些困难题时，孩子能够拿到一定的部分分。不过在分析正解时还是缺少点经验，比如说在做 dp 问题时，还是较难分析出题目的dp属性，后续需要加强对于难题的练习，继续加油。后续会通过反思加上总结的方法来锻炼优化建模能力。
